Workbook

Sheet 표지
B3: 14일이면 확실하게 끝낸다
B5: =SUM(목차!F6:F187)&"제" -> 1648제
B7: 공공조달관리사 2주 완성
B9: =" 실전 문제 "&SUM(목차!F6:F187)&"개로 꿰뚫는 공공조달 실무." -> 실전 문제 1648개로 꿰뚫는 공공조달 실무.
B10: 엑셀 하나로 끝내는, 무한회독 트레이닝.
B13: ▶ 지금 바로 풀어보기

Sheet 목차
A2: 공공조달관리사 필기 출제기준 (2026.03.01~2028.12.31 적용)
A3: 검정방법: 객관식 / 문제수: 80 / 시험시간: 2시간 | 과목: ① 공공조달과 법제도 이해(30) ② 공공조달계획 수립 및 분석(20) ③ 공공계약관리(30)
A5: 필기과목 | B5: 주요항목 | C5: 세부항목 | D5: 세세항목 | E5: 시트명 | F5: 생성 문제 수
A6: 1. 공공조달과 법제도 이해 | B6: 1. 공공조달 개요 | C6: 1. 공공조달의 정의 및 목적 | D6: 1. 공공조달의 정의 | E6: 1-1_공공조달개요 | F6: =COUNTIF('1-1_공공조달개요'!A:L,목차!D6) -> 16 | L6: 1-1_공공조달개요
D7: 2. 공공조달의 목적 | F7: =COUNTIF('1-1_공공조달개요'!A:L,목차!D7) -> 17 | L7: 1-2_원칙및방법
D8: 3. 공공조달의 범위 | F8: =COUNTIF('1-1_공공조달개요'!A:L,목차!D8) -> 11 | L8: 1-3_전자조달시스템
C9: 2. 공공조달 참여자, 이해관계자 | D9: 1. 공공조달 수요자 | F9: =COUNTIF('1-1_공공조달개요'!A:L,목차!D9) -> 5 | L9: 1-4_전략적공공조달
D10: 2. 공공조달 공급자 | F10: =COUNTIF('1-1_공공조달개요'!A:L,목차!D10) -> 5 | L10: 1-5_공공조달법률이해
D11: 3. 공공조달 이해관계자 | F11: =COUNTIF('1-1_공공조달개요'!A:L,목차!D11) -> 12 | L11: 1-6_공정조달관리
C12: 3. 공공조달의 특성 | D12: 1. 상업적 구매행위 특성 | F12: =COUNTIF('1-1_공공조달개요'!A:L,목차!D12) -> 7 | L12: 2-1_공공조달계획
D13: 2. 공공조달의 조달행위 특성 | F13: =COUNTIF('1-1_공공조달개요'!A:L,목차!D13) -> 23 | L13: 2-2_조달요구응대및제안
C14: 4. 공공조달의 구성체계 | D14: 1. 조직적 구성체계 | F14: =COUNTIF('1-1_공공조달개요'!A:L,목차!D14) -> 13 | L14: 2-3_입찰제안평가및계약체결
D15: 2. 감독 및 기능적 책임 | F15: =COUNTIF('1-1_공공조달개요'!A:L,목차!D15) -> 10 | L15: 3-1_계약관리일반절차
B16: 2. 공공조달 원칙 및 방법 | C16: 1. 공공조달 원칙 | D16: 1. 공공조달 기본 원칙 | E16: 1-2_원칙및방법 | F16: =COUNTIF('1-2_원칙및방법'!A:L,목차!D16) -> 26 | L16: 3-2_물품계약관리
D17: 2. 공공조달 실행 원칙 | F17: =COUNTIF('1-2_원칙및방법'!A:L,목차!D17) -> 6 | L17: 3-3_용역다수공급자계약관리
C18: 2. 공공조달 유형 | D18: 1. 중앙집중형 공공조달 | F18: =COUNTIF('1-2_원칙및방법'!A:L,목차!D18) -> 12 | L18: 3-4_공사계약관리
D19: 2. 분산형 공공조달 | F19: =COUNTIF('1-2_원칙및방법'!A:L,목차!D19) -> 6 | L19: Temp
C20: 3. 경쟁적 공공조달 방법 | D20: 1. 일반경쟁 | F20: =COUNTIF('1-2_원칙및방법'!A:L,목차!D20) -> 20
D21: 2. 제한경쟁 | F21: =COUNTIF('1-2_원칙및방법'!A:L,목차!D21) -> 9
D22: 3. 지명경쟁 | F22: =COUNTIF('1-2_원칙및방법'!A:L,목차!D22) -> 6
C23: 4. 비경쟁적 공공조달 방법 | D23: 1. 수의계약 | F23: =COUNTIF('1-2_원칙및방법'!A:L,목차!D23) -> 27
D24: 2. 소액구매 | F24: =COUNTIF('1-2_원칙및방법'!A:L,목차!D24) -> 9
B25: 3. 전자조달시스템 | C25: 1. 전자조달시스템 개요 | D25: 1. 전자조달시스템 개념 | E25: 1-3_전자조달시스템 | F25: =COUNTIF('1-3_전자조달시스템'!A:L,목차!D25) -> 7
D26: 2. 전자조달시스템 유형 | F26: =COUNTIF('1-3_전자조달시스템'!A:L,목차!D26) -> 3
D27: 3. 전자조달시스템 운영환경 | F27: =COUNTIF('1-3_전자조달시스템'!A:L,목차!D27) -> 5
D28: 4. 전자조달시스템 구성요소 | F28: =COUNTIF('1-3_전자조달시스템'!A:L,목차!D28) -> 3
D29: 5. 전자조달시스템 기능 | F29: =COUNTIF('1-3_전자조달시스템'!A:L,목차!D29) -> 6
D30: 6. 전자조달시스템 도입 성과 | F30: =COUNTIF('1-3_전자조달시스템'!A:L,목차!D30) -> 7
C31: 2. 국가종합전자조달시스템(나라장터) 연계 계약 관리 지원시스템 개요 | D31: 1. 종합쇼핑몰 이용절차 | F31: =COUNTIF('1-3_전자조달시스템'!A:L,목차!D31) -> 16
D32: 2. 혁신장터 활용 계약 | F32: =COUNTIF('1-3_전자조달시스템'!A:L,목차!D32) -> 3
D33: 3. 벤처나라 활용 계약 | F33: =COUNTIF('1-3_전자조달시스템'!A:L,목차!D33) -> 8
D34: 4. 디지털서비스몰 활용 계약 | F34: =COUNTIF('1-3_전자조달시스템'!A:L,목차!D34) -> 1
D35: 5. 이음장터 활용 계약 | F35: =COUNTIF('1-3_전자조달시스템'!A:L,목차!D35) -> 2
C36: 3. 목록정보시스템 개요 | D36: 1. 물품목록법령의 개요 | F36: =COUNTIF('1-3_전자조달시스템'!A:L,목차!D36) -> 7
D37: 2. 목록정보시스템 이용 일반절차 | F37: =COUNTIF('1-3_전자조달시스템'!A:L,목차!D37) -> 7
D38: 3. 목록정보시스템 활용 목록화 절차 | F38: =COUNTIF('1-3_전자조달시스템'!A:L,목차!D38) -> 4
D39: 4. 목록정보시스템 활용 분류·품명·품목 관리 절차 | F39: =COUNTIF('1-3_전자조달시스템'!A:L,목차!D39) -> 9
D40: 5. 목록정보시스템 활용 최신화 및 분류 정비 | F40: =COUNTIF('1-3_전자조달시스템'!A:L,목차!D40) -> 2
D41: 6. 목록정보시스템 활용 분류체계 국제 표준화 | F41: =COUNTIF('1-3_전자조달시스템'!A:L,목차!D41) -> 1
B42: 4. 전략적 공공조달 | C42: 1. 중소기업지원 조달 | D42: 1. 중소기업과 공공구매제도 이해 | E42: 1-4_전략적공공조달 | F42: =COUNTIF('1-4_전략적공공조달'!A:L,목차!D42) -> 8
...

Sheet 1-6_공정조달관리
A2: 공공조달과 법제도 이해 - 6. 공정조달 관리
A3: 번호 | B3: 세부항목 | C3: 세세항목 | D3: 문제 내용 | E3: 보기① | F3: 보기② | G3: 보기③ | H3: 보기④ | I3: 정답 번호 | J3: 해설 및 오답노트 | K3: 출처 | L3: 구분
A4: 1 | B4: 1. 공공조달 법규 분쟁 및 해석 | C4: 1. 공공조달 분쟁조정 | D4: 공공조달 계약 분쟁에서 국가계약분쟁조정위원회의 조정을 거쳐 당사자가 조정안을 수락했을 때 발생하는 법적 효력은? | E4: 법원의 별도 확인 없이는 효력이 없다 | F4: 재판상 화해와 동일한 효력을 갖는다 | G4: 단순한 민사상 합의에 불과하다 | H4: 행정청 내부 참고자료로만 활용된다 | I4: 2 | J4: * 정답 (②): 조정안을 당사자가 수락하면 재판상 화해와 동일한 효력을 가져, 소송 없이도 확정판결과 같은 효력이 부여됨. | K4: 국가계약법 제29조
A5: 2 | B5: 1. 공공조달 법규 분쟁 및 해석 | C5: 1. 공공조달 분쟁조정 | D5: [상황] A사는 낙찰자 결정에 불만이 있어 국가계약분쟁조정위원회에 조정을 신청하려 한다. 이 위원회에 조정을 신청할 수 있는 사안으로 가장 적절한 것은? | E5: 타 회사 간의 순수한 상거래 채권 분쟁 | F5: 계약과 무관한 친족 간 재산 상속 분쟁 | G5: 국가계약법의 적용을 받는 계약 과정에서 발생한 입찰·낙찰 관련 분쟁 | H5: 직원 개인의 이직 관련 근로계약 분쟁 | I5: 3 | J5: * 정답 (③): 국가계약분쟁조정위원회는 국가계약법 적용을 받는 계약 과정에서 발생한 분쟁(낙찰자결정, 계약금액조정, 제재처분 이의 등)을 조정 대상으로 하며, 계약과 무관한 사적 분쟁은 대상이 아님. | K5: 국가계약법 제28조·제29조
A6: 3 | B6: 1. 공공조달 법규 분쟁 및 해석 | C6: 2. 유권해석 및 감사사례 | D6: 국가계약법과 조달사업법 각각에 대한 유권해석 소관을 비교한 설명으로 가장 옳은 것은? | E6: 국가계약법은 소관 부처인 재정경제부가, 조달사업법은 소관 부처인 조달청이 각각 유권해석을 담당한다 | F6: 두 법 모두 조달청이 유권해석 권한을 가진다 | G6: 유권해석 권한은 법원에만 있고 행정부처에는 없다 | H6: 두 법 모두 감사원이 유권해석 권한을 가진다 | I6: 1 | J6: * 정답 (①): 각 법령의 유권해석은 해당 법령의 소관 부처가 담당하는 것이 원칙이며, 국가계약법은 재정경제부, 조달사업법은 조달청이 소관 부처임.
A7: 4 | B7: 1. 공공조달 법규 분쟁 및 해석 | C7: 2. 유권해석 및 감사사례 | D7: [상황] 한 공공기관의 계약 업무 처리 과정에서 법규 위반 소지가 있다는 민원이 제기되어, 헌법기관인 감사기구가 직권으로 조사에 착수했다. 이 조사를 담당하는 기관으로 가장 적절한 것은? | E7: 국무조정실 | F7: 국회 예산정책처 | G7: 감사원 | H7: 공정거래위원회 | I7: 3 | J7: * 정답 (③): 헌법기관인 감사원은 국가 및 법률이 정한 단체의 회계검사와 행정기관·공무원의 직무감찰을 담당하며, 계약업무의 위법·부당 여부를 조사해 시정을 요구할 수 있음.
A8: 5 | B8: 1. 공공조달 법규 분쟁 및 해석 | C8: 3. 계약보증금 쟁점 | D8: [상황] 계약상대자의 귀책사유로 계약이 해제되었다. 이때 뒤따르는 계약보증금 관련 조치로 가장 적절한 것은? | E8: 납부된 계약보증금이 국고에 귀속될 수 있다 | F8: 납부된 계약보증금이 즉시 반환된다 | G8: 계약보증금은 자동으로 하자보수보증금으로 전환된다 | H8: 계약보증금 관련 규정은 적용되지 않는다 | I8: 1 | J8: * 정답 (①): 계약상대자의 귀책사유로 계약이 해제·해지되면, 계약이행 담보를 위해 납부한 계약보증금은 국고에 귀속될 수 있음. | K8: 국가계약법 시행령 제52조
A9: 6 | B9: 1. 공공조달 법규 분쟁 및 해석 | C9: 3. 계약보증금 쟁점 | D9: 계약보증금과 관련한 쟁점 중, 계약이 정상적으로 이행 완료된 경우의 처리로 가장 적절한 것은? | E9: 국고에 귀속되는 것이 원칙이다 | F9: 계약상대자에게 반환되는 것이 원칙이다 | G9: 발주기관이 임의로 사용할 수 있다 | H9: 차기 계약의 입찰보증금으로 자동 전환된다 | I9: 2 | J9: * 정답 (②): 계약이 정상적으로 이행·완료되면 담보 목적이 소멸하므로 계약보증금은 계약상대자에게 반환되는 것이 원칙임. | K9: 국가계약법 시행령 제52조
A10: 7 | B10: 1. 공공조달 법규 분쟁 및 해석 | C10: 4. 부정당제재 처분 법리 | D10: [상황] 계약담당공무원이 특정 업체에 대해 법령상 상한에 가까운 최장 기간의 부정당업자 제재를 부과하면서, 그 업체에게 사전에 의견을 제출할 기회를 전혀 주지 않았다. 이 처분에 대한 법원의 판단으로 가장 타당한 것은? | E10: 처분청의 재량이므로 법원은 심사할 수 없어 그대로 유효하다 | F10: 의견 제출 기회는 법적으로 요구되지 않으므로 문제되지 않는다 | G10: 절차적 정당성이 결여되었거나 재량권 일탈·남용이 인정되면 위법하다고 판단해 취소될 수 있다 | H10: 제재 기간의 장단과 무관하게 항상 적법하다 | I10: 3 | J10: * 정답 (③): 부정당업자 제재는 국민의 권리를 제한하는 행정처분이므로, 의견 제출 기회 등 절차적 정당성이 결여되거나 재량권 일탈·남용이 인정되면 법원이 위법하다고 판단해 취소할 수 있음.
A11: 8 | B11: 1. 공공조달 법규 분쟁 및 해석 | C11: 4. 부정당제재 처분 법리 | D11: 부정당업자 제재 처분의 요건·절차에 대한 법원의 심사 태도로 가장 적절한 것은? | E11: 제재 사유의 존부만 확인하고 절차는 심사하지 않는다 | F11: 처분청의 판단을 그대로 존중해 사실상 심사하지 않는다 | G11: 제재의 정도는 심사 대상에서 완전히 제외한다 | H11: 요건 해당 여부, 절차적 정당성, 제재 정도의 적정성을 종합적으로 심사한다 | I11: 4 | J11: * 정답 (④): 법원은 부정당업자 제재가 권리를 제한하는 행정처분이므로 요건·절차·비례원칙 등을 종합적으로 심사함.
A12: 9 | B12: 1. 공공조달 법규 분쟁 및 해석 | C12: 5. 허위서류 관련 쟁점 | D12: [상황] 낙찰자로 결정된 업체가 제출한 실적증명서가 허위로 작성된 사실이 계약체결 이후에 확인되었다. 이 경우 발주기관이 취할 수 있는 조치로 가장 적절한 것은? | E12: 형사처벌만 가능하고 계약상 조치는 불가능하다 | F12: 계약의 해제·해지, 손해배상 청구, 부정당업자 제재 등의 조치를 검토할 수 있다 | G12: 허위서류 여부와 무관하게 계약을 그대로 유지해야 한다 | H12: 이미 계약이 체결되었으므로 아무 조치도 할 수 없다 | I12: 2 | J12: * 정답 (②): 허위서류로 낙찰·계약체결한 사실이 확인되면 계약의 해제·해지, 손해배상 청구, 부정당업자 제재 등이 함께 검토될 수 있음. | K12: 국가계약법 시행령 제75조·제76조 등 관련 규정
A13: 10 | B13: 1. 공공조달 법규 분쟁 및 해석 | C13: 5. 허위서류 관련 쟁점 | D13: 입찰참가자격 서류나 실적증명서 등을 허위로 작성해 제출하는 행위가 공공조달 계약질서에 미치는 영향으로 가장 적절한 것은? | E13: 행정절차를 단순화하는 긍정적 효과가 있다 | F13: 허위서류라도 결과만 좋으면 문제되지 않는다 | G13: 다른 입찰참가자에게 아무런 영향을 주지 않는다 | H13: 공정한 경쟁을 저해하고 계약이행능력 심사의 신뢰성을 훼손한다 | I13: 4 | J13: * 정답 (④): 허위서류 제출은 계약이행능력 심사의 전제 자체를 왜곡해 공정한 경쟁을 저해하므로 엄격히 다뤄짐.
A14: 11 | B14: 2. 법규 위반시 제재 | C14: 1. 계약의 해제 및 해지 | D14: 계약상대자의 귀책사유로 계약이 해제되는 경우와 발주기관 사정으로 계약이 해지되는 경우를 비교한 설명으로 가장 적절한 것은? | E14: 귀책사유와 무관하게 처리 결과는 동일하다 | F14: 전자는 부정당업자 제재 등 불이익 조치가 뒤따를 수 있으나, 후자는 계약상대자에게 불이익이 가지 않는 방향으로 처리된다 | G14: 두 경우 모두 계약상대자에게 동일한 불이익이 발생한다 | H14: 발주기관 사정으로 인한 해지 시에도 항상 부정당업자로 제재된다 | I14: 2 | J14: * 정답 (②): 계약상대자 귀책사유로 인한 해제는 보증금 국고귀속·부정당업자 제재 등 불이익이 따르지만, 발주기관 사정으로 인한 해지는 계약상대자에게 불이익이 가지 않도록 처리되는 것이 원칙임. | K14: 국가계약법 시행령 제75조·제76조
A15: 12 | B15: 2. 법규 위반시 제재 | C15: 1. 계약의 해제 및 해지 | D15: 계약 해제·해지 시 이미 이행된 부분에 대한 처리로 가장 적절한 것은? | E15: 이미 이행된 부분에 대해서는 정산해 대가를 지급하는 것이 원칙이다 | F15: 이미 이행된 부분도 전부 무효로 처리한다 | G15: 발주기관이 임의로 지급 여부를 정한다 | H15: 귀책사유와 무관하게 대가를 전혀 지급하지 않는다 | I15: 1 | J15: * 정답 (①): 계약이 해제·해지되더라도 이미 이행된 부분에 대해서는 정산 절차를 거쳐 대가를 지급하는 것이 원칙임.
A16: 13 | B16: 2. 법규 위반시 제재 | C16: 2. 부정당업자 제재 | D16: [상황] B사는 X기관과의 계약에서 부정당업자로 제재를 받았다. 이후 B사가 Y기관이 발주하는 별도의 입찰에 참가하려 할 때의 효력으로 가장 적절한 것은? | E16: 제재 효력은 같은 지역의 기관에만 미친다 | F16: X기관 발주 입찰에서만 제한되고 Y기관 입찰 참가에는 영향이 없다 | G16: 국가계약법 적용을 받는 공공기관이라면 Y기관의 입찰 참가도 제한될 수 있다 | H16: 제재 효력은 발주기관이 명시적으로 통보한 기관에만 미친다 | I16: 3 | J16: * 정답 (③): 부정당업자 제재는 특정 발주기관에 한정되지 않고, 국가계약법의 적용을 받는 모든 공공기관의 입찰 참가를 제한하는 효력을 가짐. | K16: 국가계약법 제27조
A17: 14 | B17: 2. 법규 위반시 제재 | C17: 2. 부정당업자 제재 | D17: 다음 조치 중 성격이 나머지 셋과 가장 다른 하나는? | E17: 불공정 조달행위에 대해 과징금을 부과하는 것 | F17: 계약 위반에 따른 손해를 배상받기 위해 민사소송을 제기하는 것 | G17: 계약보증금을 국고에 귀속시키는 것 | H17: 부정당업자로 지정해 향후 입찰참가자격을 제한하는 것 | I17: 2 | J17: * 정답 (②): 손해배상을 구하는 민사소송은 계약당사자 간 채무불이행에 대한 사법적 구제절차이고, 나머지는 조달질서 유지를 위해 행정적으로 부과되는 제재의 성격을 가짐.
A18: 15 | B18: 2. 법규 위반시 제재 | C18: 3. 불공정조달행위 제재 | D18: [상황] 계약담당공무원 C는 다음 네 가지 행위 중 하나만 실제로 계약관리 업무에서 정당하게 허용되는 행위임을 알고 있다. 허용되는 행위로 가장 적절한 것은? | E18: 특정 업체만 충족 가능하도록 규격을 좁게 설정하는 행위 | F18: 법령을 위반해 특정인에게만 입찰참가자격을 부여하는 행위 | G18: 조달사업의 공정성을 해치는 것으로 대통령령이 정하는 그 밖의 행위를 하는 행위 | H18: 계약조건에 명시된 기준에 따라 이행지체에 대한 지체상금을 부과하는 행위 | I18: 4 | J18: * 정답 (④): 계약조건에 따른 지체상금 부과는 정당한 계약관리 행위이며, 나머지는 조달사업법상 금지되는 불공정 조달행위의 예시에 해당함. | K18: 조달사업에 관한 법률 제22조
A19: 16 | B19: 2. 법규 위반시 제재 | C19: 3. 불공정조달행위 제재 | D19: 불공정 조달행위 신고에 따른 조달청장의 조사 결과, 위반 사실이 확인된 경우 취할 수 있는 조치로 가장 거리가 먼 것은? | E19: 관계 기관에 관련 공무원의 징계를 요구하는 것 | F19: 수사기관에 고발하거나 수사를 의뢰하는 것 | G19: 위반 사실에 대한 시정조치를 명하는 것 | H19: 조달청장이 직접 재판을 진행해 형을 선고하는 것 | I19: 4 | J19: * 정답 (④): 조달청장은 시정조치 명령, 징계 요구, 필요시 수사기관에 고발·수사의뢰는 할 수 있으나, 재판을 직접 진행해 형을 선고하는 사법권은 없음.
A20: 17 | B20: 2. 법규 위반시 제재 | C20: 3. 불공정조달행위 제재 | D20: [상황] D사가 다른 업체와 담합해 입찰에 참여한 사실이 적발되었다. D사가 받게 될 결과로 가장 거리가 먼 것은? | E20: 그 공로를 인정받아 우수조달물품으로 신규 지정된다 | F20: 공정거래위원회로부터 과징금을 부과받을 수 있다 | G20: 부정당업자로 지정되어 입찰참가자격이 제한된다 | H20: 관련 임직원이 형사처벌을 받을 수 있다 | I20: 1 | J20: * 정답 (①): 담합은 불법행위로 각종 제재의 대상이 될 뿐, 오히려 이를 이유로 우수조달물품으로 신규 지정되는 일은 있을 수 없으며 기존 지정도 취소·제한될 수 있음.
A21: 18 | B21: 2. 법규 위반시 제재 | C21: 4. 부당이득금 환수 | D21: [상황] 계약상대자가 관계 법령을 위반해 부당한 방법으로 계약금액을 초과 지급받은 사실이 확인되었다. 이 경우 발주기관이 취할 수 있는 조치로 가장 적절한 것은? | E21: 부당이득에 해당하는 금액을 환수하는 절차를 진행할 수 있다 | F21: 계약상대자의 향후 실적으로만 반영한다 | G21: 초과 지급된 금액을 그대로 인정하고 넘어간다 | H21: 다음 계약에서 자동으로 상계 처리된다 | I21: 1 | J21: * 정답 (①): 부당한 방법으로 초과 지급받은 금액이 확인되면, 발주기관은 이를 부당이득으로 보아 환수하는 절차를 진행할 수 있음.
A22: 19 | B22: 2. 법규 위반시 제재 | C22: 4. 부당이득금 환수 | D22: 부당이득금 환수 제도의 취지로 가장 적절한 것은? | E22: 계약상대자에게 최대한의 이익을 보장하기 위해 | F22: 행정절차를 신속하게 종결하기 위해 | G22: 법령을 위반해 부당하게 얻은 이익을 원상회복시켜 조달질서의 공정성을 확보하기 위해 | H22: 발주기관의 예산을 늘리기 위해 | I22: 3 | J22: * 정답 (③): 부당이득금 환수는 위법·부당한 방법으로 얻은 이익을 원상회복시켜 조달질서의 공정성을 확보하려는 취지임.
A23: 20 | B23: 2. 법규 위반시 제재 | C23: 2. 부정당업자 제재 | D23: 정부계약 이행 과정에서 뇌물수수나 조세포탈 등으로 유죄 판결이 확정된 자에 대하여 입찰참가자격을 제한하는 경우, 판결 확정일로부터 몇 년이 경과해야 참가가 허용되는가? | E23: 유죄 판결 확정일로부터 2년 경과 | F23: 유죄 판결 확정일로부터 3년 경과 | G23: 유죄 판결 확정일로부터 5년 경과 | H23: 유죄 판결 확정일로부터 10년 경과 | I23: 1 | J23: * 정답 (①): 조세포탈 등으로 형벌을 받은 자는 해당 유죄 판결이 확정된 날부터 '2년'이 지나야만 공공기관 입찰에 다시 참여할 수 있는 자격을 회복합니다. | K23: 국가계약법 제27조의5
A24: 21 | B24: 2. 법규 위반시 제재 | C24: 1. 계약의 해제 및 해지 | D24: 계약상대자의 귀책사유로 인한 계약의 해제·해지에 대한 설명으로 가장 올바른 것은? | E24: 청렴서약서 내용을 중대하게 위반한 사실이 확인되더라도, 계약이 이미 이행 중이라면 해당 계약을 도중에 해제하거나 해지할 법적 근거는 없다. | F24: 지체상금이 계약금액의 10% 이상 발생했음에도 발주기관이 계약을 해제하지 않을 경우, 기존 계약보증금은 즉시 전액 환급 처리해야 한다. | G24: 입찰 과정에서 거짓 서류를 제출하여 낙찰받은 사실이 적발되더라도 이미 정상적으로 계약이 체결되었다면 이를 소급하여 해제할 수 없다. | H24: 계약 해제 또는 해지 조치가 선행되지 않고서는 단지 정부가 필요하다는 이유만으로 계약상대자의 계약보증금을 단독으로 국고에 귀속시킬 수 없다. | I24: 4 | J24: * 정답 (④): 계약보증금의 국고 귀속은 '계약 해제/해지' 사유가 발생하여 해당 행정 조치를 취할 때 수반되는 것이므로, 원인이 되는 해제·해지 조치 없이는 보증금만 따로 귀속시킬 수 없습니다. (오답 노트: ① 법 제5조의3에 따라 청렴서약서 위반 시 계약 해제·해지 가능, ② 시행령 제51조에 따라 계약보증금을 '추가로 납부'하게 해야 함, ③ 재경부 계약예규 및 지방계약법 제30조의2 제1항 제3호에 따라 거짓 서류 제출 시 계약 체결 후라도 명백한 해제·해지 사유임) | K24: 「국가계약법」 제5조의3 및 동법 시행령 제51조, 제75조, 지방계약법 제30조의2
A25: 22 | B25: 2. 법규 위반시 제재 | C25: 2. 부정당업자 제재 | D25: 공정경쟁 질서 확립을 위한 부정당업자의 입찰참가자격 제한 제도에 대한 설명으로 가장 올바른 것은? | E25: 사용인(직원)이 부정행위를 저지른 경우, 대표자가 위반행위를 방지하기 위해 상당한 주의와 감독을 기울였음을 입증하더라도 대표자의 자격을 무조건 제한해야 한다. | F25: 부정당업자 제재 처분을 받아 입찰참가자격이 제한된 업체는 경쟁입찰뿐만 아니라 예외적인 수의계약 체결 대상에서도 원천적으로 배제된다. | G25: 국가기관이 부정당업자의 입찰참가자격을 제한할 때는 신속한 행정 처리를 위해 계약심의위원회의 자문 절차를 전면 생략하는 것이 원칙이다. | H25: 담합이나 뇌물 제공 등 중대한 부정행위라도 처분 시효 규정에 따라 해당 행위 종료 후 3년만 경과하면 입찰 참가자격을 제한할 수 없다. | I25: 2 | J25: * 정답 (②): 부정당업자로 지정되어 제재 기간 중에 있는 업체는 경쟁입찰 참가 자격이 박탈될 뿐만 아니라, 국가계약법령상 예외적인 '수의계약' 대상자에서도 제외되어 공공조달 시장 진입이 전면 차단됩니다. (오답 노트: ① 법 제27조 제1항 단서에 따라 상당한 주의와 감독을 게을리하지 않은 경우 양벌규정에서 면책됨, ③ 자문(심의)을 생략하는 것이 아니라 원칙적으로 계약심의위원회의 심의를 거쳐야 함, ④ 처분 제척기간은 원칙적으로 5년이며 담합 및 뇌물 제공 등은 7년임) | K25: 「국가계약법」 제27조 및 동법 시행령 제76조
A26: 23 | B26: 2. 법규 위반시 제재 | C26: 2. 부정당업자 제재 | D26: 부정당업자 제재 처분의 효력 범위 및 절차에 대한 설명으로 가장 올바른 것은? | E26: 부정당업자 제재 처분은 처분청의 관할과 무관하게 통합되어, 다른 모든 중앙관서 및 지방자치단체 등 공공부문 전체에 그 효력이 미친다. | F26: 발주기관이 특정 업체의 입찰참가자격을 제한한 경우, 해당 제한 내용은 별도 전산망이 아닌 기관 내부 게시판에만 15일간 공지하면 된다. | G26: 공동계약에 참여한 공동수급체 중 1인이 제재 사유를 유발한 경우, 연대책임을 물어 원인 제공 여부와 무관하게 구성원 전원의 자격을 즉시 제한해야 한다. | H26: 법인이 공공조달 입찰 과정에서 부정당업자 제재를 받은 경우, 그 처분의 법적 효력은 법인에만 미치며 해당 행위를 직접 지시한 대표자 개인에게는 적용되지 않는다. | I26: 1 | J26: * 정답 (①): A라는 중앙관서나 지자체에서 부정당업자 제재를 내리더라도 그 처분은 통합시스템을 통해 연계되어, 전국 모든 공공기관, 지자체, 공기업 및 준정부기관의 입찰에 참여할 수 없게 됩니다. | K26: 「국가계약법 시행령」 제76조
A27: 24 | B27: 2. 법규 위반시 제재 | C27: 2. 부정당업자 제재 | D27: 입찰참가자격 제한 처분에 갈음하여 부과되는 과징금 제도에 대한 설명으로 가장 올바른 것은? | E27: 부과된 과징금을 납부 기한까지 미납할 경우, 발주기관의 장은 국세징수법이 아닌 별도의 민사소송을 통해서만 체납액을 강제 회수할 수 있다. | F27: 입찰참가자격 제한에 갈음하여 부과된 과징금은 업체의 자금 경색 등 어떠한 사유로도 납부 기한을 연장하거나 분할하여 납부할 수 없다. | G27: 과징금은 단순히 계약금액의 10%로 일괄 부과되는 것이 아니라, 위반 행위의 경중에 따라 계약금액의 100분의 30 이내에서 세부 기준에 맞추어 산정된다. | H27: 부정당업자가 대체 부과된 과징금을 성실히 전액 납부하더라도, 원래 부과받은 입찰참가자격 제한 기간은 취소되지 않고 중복 적용된다. | I27: 3 | J27: * 정답 (③): 과징금은 위반 행위의 종류와 경중에 따라 계약금액의 10% 단위로 고정되는 것이 아니라, 법정 산정 기준에 따라 계약금액의 100분의 30 이하(최대 한도) 내에서 차등 산정하여 부과됩니다. (오답 노트: ① 과징금 미납 시 별도 민사소송이 아닌 '국세 체납처분의 예'에 따라 강제 징수함(법 제27조의2), ② 재해나 자금 경색 등 일정 요건 충족 시 납부기한 연장 및 분할납부가 가능함(시행령 제76조의2), ④ 과징금은 입찰참가자격 제한 처분에 '갈음하여(대신하여)' 부과하는 것이므로 자격 제한과 중복 적용되지 않음) | K27: 「국가계약법」 제27조의2 및 동법 시행령 제76조의2
A28: 25 | B28: 1. 공공조달 법규 분쟁 및 해석 | C28: 1. 공공조달 분쟁조정 | D28: 국가계약분쟁조정위원회에 대한 설명으로 옳지 않은 것은? | E28: 「국가계약법」 제29조에 근거하여 설치된다. | F28: 각 중앙관서에 설치되어 계약 관련 분쟁을 조정한다. | G28: 조정 성립 시 재판상 화해와 동일한 효력을 가진다. | H28: 이미 소송이 진행 중인 사안에 대해서도 조정 신청이 가능하다. | I28: 4 | J28: * 정답 (④): 「국가계약법 시행령」 제101조에 따라 이미 소송이 계속 중이거나 분쟁조정이 성립된 사항에 대해서는 조정 신청이 제한된다.
A29: 26 | B29: 1. 공공조달 법규 분쟁 및 해석 | C29: 2. 유권해석 및 감사사례 | D29: 법령 해석의 효력 순위가 올바르게 나열된 것은? | E29: 행정해석 > 정부유권해석 > 사법해석 | F29: 정부유권해석 > 사법해석 > 행정해석 | G29: 사법해석 > 정부유권해석 > 행정해석 | H29: 사법해석 = 정부유권해석 > 행정해석 | I29: 3 | J29: * 정답 (③): 법원의 사법해석이 가장 우선하며, 법제처의 정부유권해석이 개별 행정기관의 행정해석보다 상위의 효력을 가진다.
A30: 27 | B30: 1. 공공조달 법규 분쟁 및 해석 | C30: 3. 계약보증금 쟁점 | D30: 지체상금이 계약보증금 상당액에 달한 경우의 처리로 옳은 것은? | E30: 지체상금이 계약보증금에 도달하면 자동으로 계약이 해제된다. | F30: 이행 가능성이 있으면 추가 계약보증금을 징수하여 계약을 유지할 수 있다. | G30: 발주기관이 별도의 판단 없이 반드시 해제·해지해야 한다. | H30: 지체상금이 계약보증금에 도달해도 계약 해제·해지 사유에 해당하지 않는다. | I30: 2 | J30: * 정답 (②): 「국가계약법 시행령」 제75조에 따라 지체상금이 계약보증금 상당액에 달하더라도, 이행 가능성과 유지 필요성이 있으면 추가 계약보증금 징수 후 계약 유지가 가능하다.
A31: 28 | B31: 1. 공공조달 법규 분쟁 및 해석 | C31: 4. 부정당제재 처분 법리 | D31: 부정당업자 제재와 적격심사의 관계에 대한 설명으로 옳은 것은? | E31: 부정당업자 제재 사유에 해당하면 적격심사 대상에서 즉시 배제한다. | F31: 적격심사와 부정당업자 제재는 별개 제도이므로 제재 확정 전 임의 배제 불가 | G31: 부정당업자 제재 처분이 확정되면 소급하여 적격심사 결과를 무효로 한다. | H31: 적격심사 과정에서 부정당업자 제재 사유 발견 시 제제가 자동 확정된다. | I31: 2 | J31: * 정답 (②): 적격심사는 낙찰자를 결정하기 위한 별도의 평가절차이고, 부정당업자 제재는 입찰 참가 자격을 제한하는 행정처분으로서 양자는 별개의 제도이다. 따라서 제재 확정 전 임의 배제는 불가하다.
A32: 29 | B32: 1. 공공조달 법규 분쟁 및 해석 | C32: 5. 허위서류 관련 쟁점 | D32: 허위실적 서류를 제출하여 낙찰받은 자에 대한 조치로 옳은 것은? | E32: 허위 실적을 제외해도 적격심사 기준을 충족하면 제재 없이 계약 유지 | F32: 허위서류 제출 자체가 계약 해제 사유이며 부정당업자 제재도 가능하나, 계약보증금 국고 귀속은 불가 | G32: 계약 해제, 부정당업자 제재, 계약보증금 국고 귀속이 모두 가능 | H32: 허위서류 제출이 고의가 아닌 단순 실수인 경우 시정 기회를 부여한다. | I32: 3 | J32: * 정답 (③): 허위서류 제출 자체가 계약 해제 및 부정당업자 제재 사유에 해당하며(심사 결과 영향·고의 여부 불문), 이는 계약상대자의 귀책사유(거짓이나 그 밖의 부정한 방법으로 계약 체결)에 따른 계약 해제이므로 계약보증금 역시 국고에 귀속된다.
A33: 30 | B33: 1. 공공조달 법규 분쟁 및 해석 | C33: 1. 공공조달 분쟁조정 | D33: 공공조달 법규 분쟁 및 해석의 기본 개념/원칙으로 가장 적절한 것은? | E33: 기준·절차를 사전에 명확히 하고 동일하게 적용하여 공정성과 투명성을 확보한다. | F33: 구두 합의가 문서보다 우선한다. | G33: 상황에 따라 사후에 기준을 바꾸어도 무방하다. | H33: 담당자 편의에 따라 공개·기록을 생략할 수 있다. | I33: 1 | J33: * 정답 (①): 원칙(사전확정·공개·기록·동일적용)은 감사·분쟁 리스크를 줄이는 핵심이다.
A34: 31 | B34: 1. 공공조달 법규 분쟁 및 해석 | C34: 1. 공공조달 분쟁조정 | D34: 다음 중 공공조달 법규 분쟁 및 해석 관련 실무통제(리스크 관리)로 가장 적절한 것은? | E34: 요구사항·평가기준·검수기준·변경절차를 문서화하고 이해관계자에게 사전 공유한다. | F34: 검수는 생략하고 하자 발생 시 추후 협의한다. | G34: 계약조건은 낙찰자와 구두로만 정한다. | H34: 평가기준은 입찰 마감 후 필요에 따라 조정한다. | I34: 1 | J34: * 정답 (①): 문서화+사전공유는 분쟁 예방, 성과관리, 책임소재 명확화에 가장 효과적이다.
A35: 32 | B35: 1. 공공조달 법규 분쟁 및 해석 | C35: 1. 공공조달 분쟁조정 | D35: 다음 중 공공조달 법규 분쟁 및 해석에 관한 설명으로 옳은 것은? | E35: 특정 업체를 지명하고 동등 이상 허용 여부는 사후 결정한다. | F35: 평가위원이 아닌 담당자 1인이 임의로 점수를 결정한다. | G35: 긴급을 이유로 공고·기록 없이 구두로 진행한다. | H35: 요구사항·평가기준·검수기준을 명확히 하고, 변경 발생 시 기록 기반으로 절차에 따라 처리한다. | I35: 4 | J35: * 정답 (④): 절차 준수와 기록(근거)은 공공조달에서 필수 요건이다.
A36: 33 | B36: 1. 공공조달 법규 분쟁 및 해석 | C36: 1. 공공조달 분쟁조정 | D36: 행정심판과 행정소송의 관계에 대한 설명으로 옳은 것은? | E36: 행정심판은 행정소송의 필수 전치절차이다. | F36: 행정심판과 행정소송은 독립적인 구제수단이다. | G36: 행정소송 제기 후 행정심판을 청구할 수 있다. | H36: 행정심판 인용 결정은 법원 판결과 동일하다. | I36: 2 | J36: * 정답 (②): 원칙적으로 행정심판과 행정소송은 독립적 구제수단이나, 법령에서 전치절차로 규정하는 경우도 있다.
A37: 34 | B37: 1. 공공조달 법규 분쟁 및 해석 | C37: 2. 유권해석 및 감사사례 | D37: 재정경제부 예규·고시의 법적 성격으로 옳은 것은? | E37: 법률과 동일한 효력을 가진다. | F37: 하위 행정규칙으로 법률에 위반할 수 없다. | G37: 법원 판결보다 우선한다. | H37: 지방자치단체에 강제력이 없다. | I37: 2 | J37: * 정답 (②): 예규·고시는 행정규칙으로 법률·시행령보다 하위에 있으며 법률에 위반되는 내용을 정할 수 없다.
A38: 35 | B38: 1. 공공조달 법규 분쟁 및 해석 | C38: 1. 공공조달 분쟁조정 | D38: 국가계약분쟁조정위원회에 분쟁조정을 신청할 수 있는 자로 옳은 것은? | E38: 발주기관만 신청 가능 | F38: 조달기업만 신청 가능 | G38: 발주기관과 조달기업 모두 신청 가능 | H38: 감사원이 신청한다. | I38: 3 | J38: * 정답 (③): 「국가계약법」 제29조에 따라 계약의 당사자인 발주기관과 계약 상대방 모두 조정을 신청할 수 있다.
A39: 36 | B39: 1. 공공조달 법규 분쟁 및 해석 | C39: 2. 유권해석 및 감사사례 | D39: 공공조달에서 '유권해석'의 의미로 가장 적절한 것은? | E39: 법원이 내리는 판결 | F39: 법령 해석 권한이 있는 기관이 내리는 공식 법령 해석 | G39: 감사원의 감사 결과 | H39: 계약 당사자 간의 합의 | I39: 2 | J39: * 정답 (②): 유권해석은 주무부처(재정경제부 등)가 법령의 의미·적용 범위에 대해 내리는 공식적 해석이다.
... A67: 64 | B67: 2. 법규 위반시 제재 | C67: 3. 불공정조달행위 제재 | D67: 「조달사업법」상 불공정조달행위의 유형으로 옳지 않은 것은? | E67: 입찰·계약서류 위·변조, 허위서류 제출 | F67: 직접생산기준 위반 납품 | G67: 원산지 거짓 표시 납품 | H67: 정상적인 가격 경쟁을 통한 낙찰 | I67: 4 | J67: * 정답 (④): 불공정조달행위는 「조달사업법」 제21조 제1항에 따라 ① 서류 위·변조, ② 직접생산기준 위반, ③ 원산지 거짓 표시, ④ 사전 승인 없이 계약규격과 다른 제품 납품, ⑤ 다수공급자계약 관련 위반, ⑥ 우수조달물품 등 부정 지정 등 6가지 유형으로 분류된다. 정상적인 가격 경쟁을 통한 낙찰은 불공정조달행위가 아니라 공공조달의 본래 운영 방식이다.

Sheet 퀴즈 모드
B2: ⚡ 계약관리 퀴즈
B3: 드롭다운에서 단어장을 선택하면 해당 시트의 문제를 즉시 불러옵니다.
B4: ▶ 단어장 선택 (시트명) | C4: 2-2_조달요구응대및제안
B5: ① 현재 문제 번호 | C5: 24 | D5: =IF($C$4="","","/ 총 "&COUNTA(INDIRECT("'"&$C$4&"'!A4:A500"))&" 문항") -> / 총 151 문항
B6: ② 내 정답 입력 (1~4)
B8: =IF($C$4="","단어장을 선택해주세요.",IFERROR(INDEX(INDIRECT("'"&$C$4&"'!D:D"),$C$5+3),"해당 번호의 문제를 찾을 수 없습니다.")) -> 조달 요구사항(Procurement Requirement) 정의 및 과업명세서 작성 시 고려하는 항목과 세부 질문의 연결로 가장 옳지 않은 것은? | I8: =IF(OR($C$4="",ISBLANK(C6)),"💡 정답 번호를 입력하면 자동으로 채점됩니다.",IF(C6=INDEX(INDIRECT("'"&$C$4&"'!I:I"),C5+3),"⭕ 정답입니다!","❌ 오답입니다! 다시 풀어보세요.")) -> 💡 정답 번호를 입력하면 자동으로 채점됩니다.
I9: =IF(OR($C$4="",ISBLANK(C6)),"","📖 [해설] "&INDEX(INDIRECT("'"&$C$4&"'!J:J"),C5+3))
B12: =IF($C$4="","","① "&IFERROR(INDEX(INDIRECT("'"&$C$4&"'!E:E"),$C$5+3),"")) -> ① 조달 배경 및 목표 - 상품, 서비스 및 공사가 필요한 이유는 무엇인가?
B13: =IF($C$4="","","② "&IFERROR(INDEX(INDIRECT("'"&$C$4&"'!F:F"),$C$5+3),"")) -> ② 이행 장소 및 방법 - 배송지(수행/시공장소)는 어디이며 어떻게 수행되는가?
B14: =IF($C$4="","","③ "&IFERROR(INDEX(INDIRECT("'"&$C$4&"'!G:G"),$C$5+3),"")) -> ③ 의사결정 체계 - 제안서 평가위원회의 개별 평가위원 명단은 누구인가?
B15: =IF($C$4="","","④ "&IFERROR(INDEX(INDIRECT("'"&$C$4&"'!H:H"),$C$5+3),"")) -> ④ 스펙 및 요구량 - 어떤 구체적인 품질 또는 수량 요구 사항을 고려해야 하는가? | I15: =IF(OR($C$4="",ISBLANK(C6)),"","§ [출처] "&INDEX(INDIRECT("'"&$C$4&"'!K:K"),C5+3))

Sheet 매크로
A1: ' 108키(풀배열) 전용 고속 퀴즈 모드 켜기
A2: Sub StartQuizMode()
A3: ' 숫자키 (상단 가로줄 & 우측 키패드 모두 적용됨. ※ Num Lock 켜짐 필수)
A4: Application.OnKey "1", "Answer1"
A5: Application.OnKey "2", "Answer2"
A6: Application.OnKey "3", "Answer3"
A7: Application.OnKey "4", "Answer4"
A9: ' 엔터키 (일반 엔터 & 우측 키패드 엔터 모두 적용)
A10: Application.OnKey "~", "NextQuestion" ' 일반 Enter
A11: Application.OnKey "{ENTER}", "NextQuestion" ' 키패드 Enter
A13: ' Page Up / Page Down (문제 앞뒤 이동)
A14: Application.OnKey "{PGUP}", "NextQuestion" ' PgUp: 다음 문제
... A65: End Sub

Sheet 매크로 사용법
B2: 1. 매크로 시트의 전체 내용 복사(ctrl + C)
B3: 2. Alt + F11
B4: 3. 삽입 > 모듈 > 붙여넣기(ctrl + V) > 닫기
B5: 4. Alt + F8
B6: 5. StartQuizMode 실행 | Q6: 매크로 동작
Q7: Enter | R7: 다음 문제
Q8: PgUp | R8: 다음 문제
Q9: PgDn | R9: 이전 문제

Sheet 1-1_공공조달개요
A2: 공공조달과 법제도 이해 - 1. 공공조달 개요
A3: 번호 | B3: 세부항목 | C3: 세세항목 | D3: 문제 내용 | E3: 보기① | F3: 보기② | G3: 보기③ | H3: 보기④ | I3: 정답 번호 | J3: 해설 및 오답노트 | K3: 출처 | L3: 개정일자 | M3: 숫자문제
A4: 1 | B4: 1. 공공조달의 정의 및 목적 | C4: 1. 공공조달의 정의 | D4: [상황] A기관은 청소용품을 가장 저렴한 가격의 업체에서 구매했고, B공사는 사회적기업이 만든 친환경 재생용지를 정책적으로 우선 구매했다. 두 사례를 공공조달의 정의 관점에서 비교한 설명으로 가장 적절한 것은? | E4: A는 전통적(협의) 관점에, B는 사회적 가치 실현 등 정책 목표를 담은 현대적(광의) 관점에 가깝다 | F4: A, B 모두 전통적(협의) 관점의 전형적 사례이다 | G4: A는 현대적 관점, B는 전통적 관점에 해당한다 | H4: 두 사례 모두 공공조달의 정의와 무관하다 | I4: 1 | J4: * 정답 (①): 단순 최저가 구매는 전통적(협의) 관점에 가깝고, 사회적 가치 실현을 목적으로 한 우선구매는 정책 수단으로서의 현대적(광의) 관점을 보여줌.
A5: 2 | B5: 1. 공공조달의 정의 및 목적 | C5: 1. 공공조달의 정의 | D5: 우리나라 조달행정이 임시외자총국 설립과 원조물자 관리를 주된 임무로 삼았던 시기로 가장 적절한 것은? | E5: 광복 이후~1960년대(전후 복구·원조물자 관리 중심) | F5: 1997년 전후(시장개방기) | G5: 2000년대 이후(전자조달 확산기) | H5: 1980년대(내자조달 확대기) | I5: 1 | J5: * 정답 (①): 광복 이후부터 1960년대까지는 6·25 전쟁 복구와 경제개발을 위한 원조물자 도입·관리가 조달행정의 중심이었고, 이 시기 임시외자총국이 설립된 뒤 조달청이 개청됨.
A6: 3 | B6: 1. 공공조달의 정의 및 목적 | C6: 1. 공공조달의 정의 | D6: 국가 및 지방자치단체가 주체가 되는 공공조달(Public Procurement)의 본질적 개념을 설명한 것으로 가장 거리가 먼 것은? | E6: 중앙관서의 장 또는 계약담당공무원이 공익 달성을 위해 민간으로부터 필요한 재화를 획득하는 일련의 과정이다. | F6: 공공기관이 자체적인 예산을 재원으로 삼아 외부의 적격한 공급자로부터 물품 및 용역을 조달받는 경제 활동이다. | G6: 수요기관이 발주한 사업에 대해 입찰 참가 자격을 갖춘 민간 기업을 평가하고 최종 계약상대자로 선정하는 절차이다. | H6: 특정 행정 기관이 자체적인 행정 수요를 충족시키기 위하여 타 국가 기관이나 지자체로부터 자산을 매입하는 행위이다. | I6: 4 | J6: * 정답 (④): 공공조달은 '공공기관(수요자)'이 자격을 갖춘 민간 '기업(공급자)'으로부터 물자나 용역을 획득하는 행위이며, 행정 기관 간의 내부 거래나 이관을 의미하지 않습니다.
A7: 4 | B7: 1. 공공조달의 정의 및 목적 | C7: 1. 공공조달의 정의 | D7: 법률적·행정적 관점에서 '공공조달(Public Procurement)'의 본질적인 정의를 가장 명확하고 오해 없이 서술한 것은? | E7: 조달청이 정부를 대표하여 단독 전담하는 제도로서, 전국의 영세한 중소기업 및 벤처기업에게 정부의 막대한 지원금을 공평하게 분배하고 기업의 성장을 돕는 일종의 재정적 복지 사업이다. | F7: 국가가 자체적인 기술로 생산하기 어려운 방산 물자나 첨단 산업 기술 제품을 외교 경로를 통해 우방국 정부로부터 직접 수입하여 국방력과 국부를 창출하는 대외 무역 상업 활동이다. | G7: 국가, 지방자치단체, 공공기관 등 공공부문이 대국민 공공서비스 제공 및 기관 운영을 위해 필수적으로 요구되는 물품, 용역, 건설공사 등을 시장의 외부 자원으로부터 획득하는 구매 절차 전반이다. | H7: 정부나 지자체가 독점적 권력을 바탕으로 민간 시장에 강제로 개입하여 주요 생필품 및 산업 원자재의 가격을 직접 통제하고 거시적인 물가를 안정화하는 일련의 직접적 시장 규제 행위이다. | I7: 3 | J7: * 정답 (③): 공공조달은 정부 등 공공부문이 자체 수요 및 공공서비스 제공에 필요한 물품, 용역, 공사를 적법한 절차에 따라 외부(민간)로부터 획득(구매)하는 행위 전반을 뜻합니다. 복지 사업이나 물가 통제 수단이 아닙니다.
A8: 5 | B8: 1. 공공조달의 정의 및 목적 | C8: 2. 공공조달의 목적 | D8: 공공조달 지출 규모가 상당한 비중을 차지한다는 점이 강조되는 이유로 가장 적절한 것은? | E8: 공공조달 지출은 절감의 여지가 전혀 없기 때문이다 | F8: 공공조달 지출의 효율성을 조금만 높여도 상당한 규모의 예산 절감·부가가치 창출 효과를 기대할 수 있기 때문이다 | G8: 공공조달은 국가 경제에서 차지하는 비중이 미미하기 때문이다 | H8: 공공조달은 민간구매보다 항상 비효율적이기 때문이다 | I8: 2 | J8: * 정답 (②): 공공조달 지출 규모가 크기 때문에 비효율성을 소폭만 제거해도 상당한 재정 절감·부가가치 창출 효과를 거둘 수 있어, 재정 운영 효율성 측면에서 그 중요성이 강조됨.
A9: 6 | B9: 1. 공공조달의 정의 및 목적 | C9: 2. 공공조달의 목적 | D9: 정부의 막대한 구매력을 지렛대 삼아 국가의 거시적 경제 성장과 사회적 가치를 견인하는 '전략적 공공조달'의 실행 방안이 아닌 것은? | E9: 자원의 재활용을 돕고 온실가스 배출을 최소화하는 친환경 제품의 구매를 의무화하는 녹색조달 제도의 적극적인 운용 | F9: 혁신적인 아이디어와 신기술을 적용한 시제품을 정부가 선도적으로 구매하여 공공서비스를 개선하는 혁신조달의 확대 | G9: 특정 대기업이나 독점적 기술을 보유한 우수 기업의 이윤을 보장하고 시장 지배력을 강화해 주기 위한 우수조달의 도입 | H9: 취약계층 일자리 창출 및 지역사회 공헌 등 경제적 이익 외의 공익적 요소를 평가에 반영하는 사회적 책임조달의 강화 | I9: 3 | J9: * 정답 (③): 전략적 공공조달의 핵심 실행 방안은 녹색조달, 혁신조달, 사회적 책임조달이며, 특정 기업의 시장 지배력을 강화하는 것은 공공조달의 목적에 위배됩니다.
A10: 7 | B10: 1. 공공조달의 정의 및 목적 | C10: 2. 공공조달의 목적 | D10: 국가 조달 제도의 역사적 발전 단계를 고찰할 때, 제도가 태동하던 '초기 단계'에서 가장 중점적으로 추구했던 정책적 목표는? | E10: 여성 기업 및 장애인 기업 등 사회적 약자를 보호하고 포용적 경제 성장을 달성하기 위한 조달 시장 진입 장벽의 완화 | F10: 친환경 자재 사용을 의무화하고 노동자의 인권을 보호하는 등 조달 과정 전반에 걸친 다양한 사회적 가치의 적극적 실현 | G10: 자국 내 유망 중소기업의 기술 경쟁력을 강화하여 글로벌 공공조달 시장(GPA)에서의 주도권과 수출 판로를 확보하는 것 | H10: 국가의 생존과 행정 운영에 필수불가결한 군수품 및 대규모 토목 자재 등의 기초 물자를 차질 없이 적시 적소에 확보하는 것 | I10: 4 | J10: * 정답 (④): 제도의 초기 형태(단순 구매 단계)는 국가 방위 및 기반 시설 구축 등 체제 유지에 필수적인 물자를 확보하는 것에 집중되었습니다.
A11: 8 | B11: 1. 공공조달의 정의 및 목적 | C11: 2. 공공조달의 목적 | D11: 현대 국가 운영에 있어 공공조달 시스템이 지니는 본질적 중요성을 가장 정확하게 짚어낸 설명은? | E11: 민간 시장 내에서 발생하는 불공정 거래 행위를 국가가 직접 규제하고 자국 산업의 피해를 구제하기 위한 법적 장치이다. | F11: 조달청을 비롯한 중앙행정기관의 업무 부담을 경감하고 행정 처리의 편의성과 효율성을 제고하기 위한 내부적 수단이다. | G11: 국가의 예산을 시장에 투입하여 정부의 정책 의지를 실물 경제 단위에서 구체적으로 집행하는 가장 핵심적인 정책 수단이다. | H11: 세계무역기구(WTO) 체제하에서 체결된 자유무역협정(FTA)을 이행하고 국제 사회와의 교역 규모를 확대하기 위한 외교 채널이다. | I11: 3 | J11: * 정답 (③): 공공조달은 단순한 물품 구매를 넘어, 세금을 재원으로 국가 정책을 실현하고 재정을 집행하는 중추적 역할을 수행합니다.
A12: 9 | B12: 1. 공공조달의 정의 및 목적 | C12: 2. 공공조달의 목적 | D12: 공공조달이 지향하는 다면적 목표 중, '정책적 측면(거시적 측면)'의 목표와 거리가 먼 것은? | E12: 공공 사업에 참여하는 공급자 간의 기회 균등을 보장하고 절차적 투명성을 엄격히 유지하는 시스템 운영상의 공정성 확보 | F12: 사회적 약자 기업에 대한 배려와 지역 경제 활성화를 도모하여 양극화를 해소하고자 하는 사회적 책임성(Social Responsibility) 강화 | G12: 민간 부문의 신기술 및 신제품 개발 투자를 유도하고 궁극적으로 대국민 공공서비스의 질적 수준을 끌어올리는 혁신(Innovation) 촉진 | H12: 제한된 자원의 효율적 사용과 탄소 중립 실현 등 미래 세대의 환경 보호를 종합적으로 고려하는 지속 가능성(Sustainability)의 유지 | I12: 1 | J12: * 정답 (①): 공정성, 투명성, 경쟁성, 비용대비 가치 등은 조달 시스템 자체를 굴러가게 하는 '운영적(미시적) 측면'의 목표입니다.
A13: 10 | B13: 1. 공공조달의 정의 및 목적 | C13: 2. 공공조달의 목적 | D13: 조달 행정이 국가 체계에서 지니는 '개념적 중요성'에 대한 철학적·행정적 설명으로 적절하지 않은 것은? | E13: 조달 과정에서 획득된 공공서비스 및 인프라의 질적 수준은 국가 정책 목표의 최종 달성 여부와 국민 삶의 질 향상에 절대적이고 직접적인 영향을 미친다. | F13: 비효율적이고 방만한 조달 운영은 단순한 행정 절차의 지연을 넘어 심각한 국가 예산의 낭비 및 거시적인 재정적 손실로 직결되는 중대한 문제를 낳는다. | G13: 현대 국가에서 공공조달은 정부의 본질적 기능을 단순히 보조하는 후선 업무가 아니라, 국가의 존립과 원활한 운영을 뒷받침하는 핵심 기능으로 격상되었다. | H13: 공공조달은 단순히 필요한 물건을 시장에서 사 오는 행위를 넘어, 국민의 세금을 재원으로 국가의 거시적 정책을 실물 경제에 투입하는 고도의 행정 수단이다. | I13: 2 | J13: * 정답 (②): 예산 낭비나 금전적 손실에 대한 설명은 조달의 '개념적 중요성'이라기보다는 '재정적 중요성'을 구체적으로 설명한 것입니다.
A14: 11 | B14: 1. 공공조달의 정의 및 목적 | C14: 2. 공공조달의 목적 | D14: 복잡다단한 법령과 규제에도 불구하고 국가 단위의 공공조달 제도가 지속적으로 존재해야 하는 가장 일차적이고 본질적인 목적은 무엇인가? | E14: 대규모 공공 발주 사업에 참여하는 다수의 민간 조달기업들에게 안정적인 일감을 제공하여 그들의 매출 및 영업 이익 극대화를 지원하기 위함이다. | F14: 국가가 국민에게 마땅히 제공해야 할 헌법적 의무인 대국민 공공서비스 유지에 필수적인 각종 자원과 인프라를 적시 적소에 안정적으로 확보하기 위함이다. | G14: 입찰 시 발생하는 업체 간의 과도한 경쟁을 억제하고 효율적인 예산 집행을 달성하여 궁극적으로 국민이 부담하는 조세부담률을 대폭 경감하기 위함이다. | H14: 국내 시장에서 검증된 우수 조달기업의 해외 진출을 국가 차원에서 적극 장려하고, 글로벌 국제 조달 시장에서의 K-조달 무역량을 확대하기 위함이다. | I14: 2 | J14: * 정답 (②): 공공조달 시스템의 제1목적은 도로, 국방, 보건, 교육 등 정부의 정상적인 기능 유지와 공공서비스 창출에 필요한 물자(공급품)를 끊김 없이 획득하는 것입니다.
A15: 12 | B15: 1. 공공조달의 정의 및 목적 | C15: 2. 공공조달의 목적 | D15: 과거 단순한 물자 획득에 치중했던 '전통적 공공조달'의 패러다임과 오늘날 거시적 목표를 지향하는 '전략적 공공조달'의 패러다임을 구분 짓는 가장 큰 핵심적 차이는 무엇인가? | E15: 조달 시장에 참여할 수 있는 대상 조달기업의 자격 요건과 진입 장벽의 완화 정도 | F15: 계약 체결부터 완료까지 소요되는 행정적 리드타임(Lead Time)의 획기적인 단축 여부 | G15: 전자조달 시스템 도입을 통해 절감된 입찰 공고 및 서류 심사 등 물리적 행정 비용 | H15: 단순 구매를 넘어 환경 보호나 일자리 창출 등 국가의 거시적 정책 목표와의 연계성 | I15: 4 | J15: * 정답 (④): 현대적 조달 체계는 물자 획득 그 자체에 머물지 않고, 막대한 조달 예산을 지렛대 삼아 국가 정책(혁신 성장 지원, 중소기업 보호, 친환경 등)을 견인하는 강력한 전략적 수단으로 진화했습니다.
... A20: 17 | B20: 1. 공공조달의 정의 및 목적 | C20: 3. 공공조달의 범위 | D20: [상황] 발주기관이 특정 조달대상물을 물품·용역·공사 중 하나로 분류하려 하는데, 담당자가 '이건 어디에도 안 들어가니 별도 범주가 필요하다'고 주장한다. 이 주장에 대한 평가로 가장 적절한 것은? | E20: 물품·용역·공사 3가지가 가장 기본적인 분류이므로, 대부분의 대상물은 이 안에서 분류할 수 있다 | F20: 모든 조달대상물은 반드시 새로운 범주를 만들어야 한다 | G20: 조달대상물은 애초에 분류 체계 자체가 없다 | H20: 물품·공사 2가지만 존재하며 용역은 별도 개념이 아니다 | I20: 1 | J20: * 정답 (①): 조달대상물의 가장 기본적인 분류는 물품·용역·공사 3가지이며, 양허권 등 특수 유형은 이보다 확장된 범주로 별도 다뤄짐.
A21: 18 | B21: 1. 공공조달의 정의 및 목적 | C21: 3. 공공조달의 범위 | D21: 조달사업에 관한 법률에서 정의하는 '조달사업'의 범위에 포함되지 않는 것은? | E21: 시설공사의 계약에 관한 사업 | F21: 물자의 공급 및 관리 | G21: 수요기관이 필요로 하는 물자의 구매 | H21: 민간기업 간의 순수한 사적 물품 거래 중개 | I21: 4 | J21: * 정답 (④): 조달사업은 수요기관의 물자 구매·공급·관리 및 시설공사 계약에 관한 사업을 의미하며, 민간기업 간 사적 거래 중개는 이에 해당하지 않음. | K21: 조달사업에 관한 법률 제2조
A22: 19 | B22: 1. 공공조달의 정의 및 목적 | C22: 3. 공공조달의 범위 | D22: 공공조달과 관련한 통계 자료를 인용할 때 확인할 사항으로 가장 적절한 것은? | E22: 오래된 자료일수록 신뢰도가 높으므로 그대로 인용한다 | F22: 구체적인 등록업체 수·비율 등의 통계는 발표 시점에 따라 달라질 수 있으므로 최신 공식 자료로 재확인하는 것이 바람직하다 | G22: 통계는 조달 실무에서 활용 가치가 없다 | H22: 통계는 한 번 발표되면 이후 변경되지 않는다 | I22: 2 | J22: * 정답 (②): 등록업체 수·비율 등 구체적 통계는 시점에 따라 변동되므로, 시험이나 실무에서 활용할 때는 최신 공식 자료(조달청 등)로 재확인하는 것이 바람직함.
A23: 20 | B23: 1. 공공조달의 정의 및 목적 | C23: 3. 공공조달의 범위 | D23: 현대적 의미의 공공조달 업무가 포괄하는 행정적·실무적 활동 범위에 대한 설명으로 가장 타당한 것은? | E23: 수요기관이 필요로 하는 유형의 물품 및 건설 자재를 민간 시장에서 단발성으로 획득하는 단순한 구매 행위 자체만을 의미한다. | F23: 입찰 공고를 게시하고 참여 업체의 적격성을 평가하여 최종적으로 가장 유리한 계약상대자를 선정하는 단계에만 엄격히 국한된다. | G23: 다수의 경쟁자 중 가장 낮은 투찰 금액을 제시한 업체를 찾아내어 국가 예산의 지출을 최소화하는 원가 절감 절차를 뜻한다. | H23: 조달 수요의 발생 및 계획 수립부터 입찰, 계약 체결, 계약 이행(납품) 관리, 그리고 사후 평가에 이르는 전체 수명 주기를 포괄한다. | I23: 4 | J23: * 정답 (④): 오늘날의 공공조달은 단순 구매(Purchasing)를 넘어 계획부터 사후관리까지의 라이프사이클 전체를 아우르는 조달(Procurement) 개념입니다.
A24: 21 | B24: 1. 공공조달의 정의 및 목적 | C24: 3. 공공조달의 범위 | D24: 국가계약법 및 관련 법령상 규정된 공공조달의 대표적인 '대상물(목적물)' 범주에 속하지 않는 것은? | E24: 교량, 도로, 항만 등 국가 기반 시설을 새롭게 조성하거나 기존의 공공 건축물을 개축 및 보수하는 대규모 건설 공사 | F24: 전문적인 지식, 기술, 노하우 등을 활용하여 국가기관에 무형의 부가가치를 제공하는 소프트웨어 개발 등의 각종 용역 | G24: 국가가 국민의 기본적인 복지와 생활 편익을 증진하기 위해 최종적인 결과물로서 대국민에게 제공하는 무상의 공공서비스 | H24: 공공기관의 원활한 행정 업무 수행과 국가 운영 인프라 유지에 필수적으로 요구되는 각종 유형의 상업적 상품 및 물품 | I24: 3 | J24: * 정답 (③): 조달의 3대 객체(대상물)는 물품, 용역, 공사입니다. 공공서비스는 이러한 조달 행위를 통해 최종적으로 달성하려는 행정적 '목적'입니다.
A25: 22 | B25: 1. 공공조달의 정의 및 목적 | C25: 3. 공공조달의 범위 | D25: 최근 수년간 공공조달 시장에서 정부가 획득하고자 하는 대상물의 범위가 단순한 규격 물품에서 시스템 통합 등 복합적이고 난해한 사업으로 크게 확대되고 있는 가장 주된 사회적 원인은? | E25: 국민의 권리 의식과 행정 기대 수준이 지속적으로 향상되고 사회 구조가 융복합됨에 따라 정부가 선제적으로 제공해야 할 공공서비스의 형태가 매우 고도화되고 다양해졌기 때문이다. | F25: 글로벌 경기 침체 및 민간 소비 시장의 장기적 위축으로 인해 새로운 캐시카우(Cash Cow)를 공공 시장에서 찾으려는 다양한 산업군의 조달기업들이 급격히 진입했기 때문이다. | G25: 부정당업자 제재 등 조달 법령상의 엄격한 진입 규제로 인해 공공조달에 상시 참여할 수 있는 역량 있는 유효 공급자의 수가 과거에 비해 절대적으로 감소하고 있기 때문이다. | H25: 복지 지출 증가에 따른 국가 재정 악화로 부처별 공공조달 예산이 매년 삭감됨에 따라, 단 한 번의 조달 발주로 여러 개의 중복된 행정 목적을 동시에 달성해야만 하기 때문이다. | I25: 1 | J25: * 정답 (①): 스마트 시티 구축, 지능형 전자정부 서비스 도입 등 정부가 해결해야 할 사회 문제(공공서비스)가 융복합화됨에 따라 조달 대상 역시 고도화된 패키지 형태로 진화하고 있습니다.
A26: 23 | B26: 1. 공공조달의 정의 및 목적 | C26: 3. 공공조달의 범위 | D26: 단순한 물자 비축에 불과했던 과거에 비해, 현대 공공조달 시장에서 국가가 획득해야 하는 대상물의 범위와 종류가 인공지능(AI), 클라우드 시스템 등으로 갈수록 비대해지고 고도화되는 가장 근본적인 이유는? | E26: 국가 세수 펑크 등 심각한 재정 부족으로 부처별 공공조달 예산이 무자비하게 삭감됨에 따라, 최소한의 한정된 비용으로 최대한의 다목적 물자를 비축해야 할 행정적 필요성 때문이다. | F26: 국민의 권리 의식 및 공공서비스에 대한 기대 수준이 크게 향상되고 사회 문제가 다변화됨에 따라 정부가 디지털 혁신 등 제공해야 할 공공서비스 자체가 고도로 복잡해지고 다양해졌기 때문이다. | G26: 글로벌 경제 위기 및 민간 시장의 고질적 소비 위축으로 인해 회사의 새로운 현금창출원(Cash Cow)을 비교적 안정적인 공공 시장에서 찾으려는 중견기업 및 대기업들이 크게 늘어났기 때문이다. | H26: 입찰 참여 자격 기준과 요구되는 재무 상태가 갈수록 엄격해짐에 따라 공공 시장 내에서 살아남은 소수의 공급자 간에만 독점적인 유효 경쟁이 심각하게 제한적으로 이루어지고 있기 때문이다. | I26: 2 | J26: * 정답 (②): 디지털 플랫폼 정부 구현 등 국가가 당면한 행정적 과제와 공공서비스의 난이도가 과거와 비할 수 없이 복잡해졌기 때문에, 조달 발주 대상 역시 단순 규격품에서 고도화된 융복합 솔루션으로 진화하는 것입니다.
A27: 24 | B27: 1. 공공조달의 정의 및 목적 | C27: 1. 공공조달의 정의 | D27: [상황] 우리나라 조달제도의 발전 과정을 시대순으로 살펴보려 한다. 다음 중 옳은 설명을 모두 고르면? (ㄱ. 1997년 WTO 정부조달협정(GPA) 가입으로 국내 조달시장이 대외에 개방되었다 ㄴ. 차세대 나라장터는 인공지능·빅데이터 등 최신 기술 기반으로 개발되었다 ㄷ. 조선시대 대동법은 현물 공납을 쌀 등으로 통일한 제도 변화였다) | E27: ㄱ만 옳다 | F27: ㄴ, ㄷ만 옳다 | G27: ㄱ, ㄴ만 옳다 | H27: ㄱ, ㄴ, ㄷ 모두 옳다 | I27: 4 | J27: * 정답 (④): GPA 가입에 따른 시장개방, 차세대 나라장터의 AI·빅데이터 기반 개발, 대동법의 현물 공납 통일이라는 세 설명 모두 옳음.
A28: 25 | B28: 2. 공공조달 참여자, 이해관계자 | C28: 1. 공공조달 수요자 | D28: [상황] 공공조달의 수요기관 유형(국가기관, 지방자치단체, 공기업, 기타 공공기관 등)별 등록 현황을 살펴볼 때 일반적으로 나타나는 경향으로 가장 적절한 것은? | E28: 전체 수요기관 중에서 국가기관이 압도적으로 높은 비중을 차지한다. | F28: 다양한 공공기관이 포함되며, 유형별 비중은 조사 시점마다 달라진다. | G28: 공공조달 수요기관으로 등록할 수 있는 자격은 공기업으로만 제한된다. | H28: 공공조달에 참여할 수 있는 수요기관의 유형은 국가기관으로 한정된다. | I28: 2 | J28: * 정답 (②): 수요기관에는 국가기관·지방자치단체·공기업·기타 공공기관 등 다양한 유형이 포함되며, 유형별 정확한 등록 비중은 조사 시점의 통계에 따라 달라질 수 있어 최신 자료 확인이 필요함.
A29: 26 | B29: 2. 공공조달 참여자, 이해관계자 | C29: 2. 공공조달 공급자 | D29: [상황] 나라장터에 등록된 조달기업 전체 중 상당수가 중소기업이라는 통계가 발표되었다. 이 통계가 시사하는 바로 가장 적절한 것은? | E29: 해당 통계는 공공조달시장 내 실제 공급자의 기업 규모별 구성 비율과는 전혀 무관한 정보이다. | F29: 중소기업이 조달시장의 대다수를 차지하여, 공공조달이 중소기업 판로 지원에 실질적으로 기여하고 있다. | G29: 현재 공공조달시장의 주요 공급망과 계약은 대부분 대기업을 위주로 집중되어 편향적으로 운영되고 있다. | H29: 자본력 등의 현실적 한계로 인하여 일반 중소기업은 공공조달시장에 원천적으로 참여할 수 없다. | I29: 2 | J29: * 정답 (②): 나라장터 등록기업의 상당수가 중소기업이라는 점은 공공조달이 중소기업 판로 지원 수단으로 실질적으로 기능할 수 있음을 보여줌(정확한 등록업체 수·비율은 조달청 최신 통계로 확인 필요).
A30: 27 | B30: 2. 공공조달 참여자, 이해관계자 | C30: 2. 공공조달 공급자 | D30: 공공조달 계약에 참여하여 사업을 수행하는 '계약상대자(조달기업)'가 지켜야 할 권리와 의무에 대한 법리적 설명으로 명백히 틀린 것은? | E30: 입찰 담합을 모의하거나 허위 서류 위변조 등 중대한 부정행위 발생 시, 국가계약법 등 관련 법령에 따라 최장 2년까지 향후 모든 공공 입찰 참가 자격이 제한(부정당업자 제재)될 수 있다. | F30: 적법한 절차를 거쳐 낙찰자로 선정되어 정식 계약을 체결한 이후에는, 천재지변 등 불가항력의 사유가 없는 한 계약서 및 과업지시서에 명시된 납품 조건과 기한을 엄격히 준수할 책임을 진다. | G30: 국가 조달 계약에서는 예산 집행 주체인 수요기관이 절대적인 우월적 지위를 가지므로, 계약상대자는 설령 부당한 과업 지시나 설계 변경 요구라 할지라도 이에 무조건적으로 복종할 법적 의무가 있다. | H30: 납품하는 재화나 제공하는 용역이 사전에 약정된 규격과 품질 기준을 완벽히 충족해야 하며, 납품 이후 일정 기간 내에 계약 목적물에 하자가 발생할 경우 법령이 정한 바에 따라 사후관리(A/S) 책임을 진다. | I30: 3 | J30: * 정답 (③): 국가계약법의 대원칙(제5조)에 따라 국가와 계약상대자는 '서로 대등한 입장에서 합의에 따라' 계약을 체결하고 신의성실의 원칙에 따라 이를 이행해야 하므로 무조건 복종할 의무는 없습니다.
A31: 28 | B31: 2. 공공조달 참여자, 이해관계자 | C31: 2. 공공조달 공급자 | D31: 공공조달 시장에 진입하여 국가기관과 지속적인 파트너십을 맺고자 하는 공급자(조달기업)에게 가장 기본적이자 최우선적으로 요구되는 핵심 윤리 요소는? | E31: 단발성 수익을 극대화하기 위해 경쟁 관계에 있는 타 업체들과 사전에 교감하여 투찰 가격을 은밀하게 모의하고 시장 질서를 교란하는 가격담합 행위 | F31: 입찰 공고문, 수요기관의 과업지시서, 국가계약법 및 하도급법 등 조달과 관련된 제반 법령과 규정을 철저히 숙지하고 한 치의 오차 없이 지키는 법규준수 행위 | G31: 입찰 적격심사 시 자사의 치명적인 결함이나 불리한 재무 상태가 감점 요소로 평가에 반영되지 않도록 신용평가 서류 조작에 적극 가담하는 정보은폐 행위 | H31: 박빙의 경쟁 상황에서 최종 낙찰 확률을 극적으로 높이기 위해 발주기관의 계약담당자나 평가위원에게 뇌물을 제공하거나 사적으로 접근하는 부정청탁 행위 | I31: 2 | J31: * 정답 (②): 입찰 담합, 부정청탁, 정보은폐 등은 모두 조달 질서를 심각하게 파괴하는 불법 행위이며, 조달 시장 참여의 대전제는 기업의 엄격한 윤리 경영과 청렴한 '법규 준수'입니다.
A32: 29 | B32: 2. 공공조달 참여자, 이해관계자 | C32: 3. 공공조달 이해관계자 | D32: [상황] 어느 위원회가 조달 행정이 법규에 맞게 집행되었는지 외부에서 점검하고 시정을 요구하는 역할을 한다고 하자. 이러한 감시·감독 기능에 가장 부합하는 기관 조합은? | E32: 나라장터 운영기관과 조달업체 협의체 | F32: 지방자치단체와 조달업체 컨소시엄 | G32: 국회와 감사원 | H32: 수요기관과 공급업체 | I32: 3 | J32: * 정답 (③): 국회와 감사원은 조달 행정 전반을 외부에서 감시·감독하고 시정을 요구하는 대표적 기관임.
A33: 30 | B33: 2. 공공조달 참여자, 이해관계자 | C33: 3. 공공조달 이해관계자 | D33: 공공조달 생태계를 구성하는 다양한 주체 중, 좁은 의미(협의)의 직접적 이해관계자로 분류하기 어려운 주체는? | E33: 수요기관의 발주 조건과 과업지시서에 맞추어 실제 재화나 용역을 납품할 의무를 지는 조달기업(공급자) | F33: 국가 예산 및 재정 집행의 적법성을 포괄적으로 감독하고 공공기관에 대한 회계 감사를 수행하는 감사원 | G33: 계약 법령과 지정된 행정 절차에 따라 상호 간에 구체적인 권리와 의무의 법률관계를 형성하는 계약 당사자 | H33: 대국민 공공서비스를 원활하게 제공하기 위해 필요 예산을 확보하고 조달 사업을 직접 발주하는 수요기관 | I33: 2 | J33: * 정답 (②): 조달을 직접 수행하는 수요기관과 기업은 '협의'의 이해관계자이며, 이를 감시하는 감사원, 국회, 일반 국민은 '광의'의 이해관계자입니다.
... A42: 39 | B42: 3. 공공조달의 특성 | C42: 2. 공공조달의 조달행위 특성 | D42: [상황] 한 담당자가 '공공조달은 원래 수의계약이 기본이고 경쟁입찰은 예외적으로만 쓰인다'고 설명했다. 이 설명에 대한 평가로 가장 적절한 것은? | E42: 틀린 설명이다. 공공조달에서 경쟁입찰과 수의계약 중 어느 것을 원칙으로 삼아야 하는지 법적으로 명확히 정해져 있지 않다. | F42: 틀린 설명이다. 공공조달 업무에서는 공급자 선정 및 계약 방법에 대해 사전에 규정된 명확한 원칙 자체가 존재하지 않는다. | G42: 틀린 설명이다. 공급자 선정은 경쟁입찰이 원칙이며, 수의계약은 관련 법령에서 정한 예외적인 사유가 있을 때만 허용된다. | H42: 옳은 설명이다. 공공조달에서는 신속한 행정 처리와 효율성 확보를 위해 수의계약을 기본적인 계약 원칙으로 채택하고 있다. | I42: 3 | J42: * 정답 (③): 공공조달의 공급자 선정은 경쟁입찰이 원칙이며, 수의계약은 법령이 정한 예외적 사유가 있을 때만 허용됨.
A43: 40 | B43: 3. 공공조달의 특성 | C43: 2. 공공조달의 조달행위 특성 | D43: [상황] 한 조달청 주무관이 신규 담당자들에게 공공계약 체결 시 준수해야 할 기본 원칙을 설명하고 있다. 이 중 적절하지 않은 발언은? | E43: 발주기관과 조달업체는 어느 한쪽으로 치우침 없이 상호 동등하고 평등한 지위에서 공정하게 계약을 맺어야 합니다. | F43: 계약 관계가 성립된 이후 양 당사자는 굳건한 신뢰를 바탕으로 합의된 내용을 성실하고 투명하게 이행해야 합니다. | G43: 공공사업의 원활한 추진을 위해 불가피한 상황이라면 업체의 정당한 이익을 일부 제한하는 특약을 설정해도 무방합니다. | H43: 계약의 성립과 세부 조건의 결정은 우월적 지위를 이용한 강요가 아닌 양측의 자율적이고 충분한 합의를 거쳐야 합니다. | I43: 3 | J43: * 정답 (③): 국가계약법상 발주기관은 어떠한 경우라도 계약상대자의 정당한 이익을 부당하게 제한하거나 침해하는 부당한 특약 및 조건을 설정할 수 없음. | K43: 국가계약법 제5조
A44: 41 | B44: 3. 공공조달의 특성 | C44: 2. 공공조달의 조달행위 특성 | D44: [상황] 한 발표자가 공공조달의 핵심원칙을 나열하며 '경쟁, 공정성, 지속가능성'을 언급했다. 다음 중 이 핵심원칙 목록에 함께 포함되기 어려운 것은? | E44: 수익성(Profitability) | F44: 책임성(Accountability) | G44: 투명성(Transparency) | H44: 효율성(Efficiency) | I44: 1 | J44: * 정답 (①): 수익성은 민간기업의 목표이며, 공공조달의 핵심원칙(경쟁·투명성·공정성·효율성·책임성·윤리성·VFM·지속가능성)에는 포함되지 않음.
A45: 42 | B45: 3. 공공조달의 특성 | C45: 2. 공공조달의 조달행위 특성 | D45: [상황] 어느 학자가 "공공조달은 단순 물품 조달에서 시작해 법령 준수, 예산의 효율적 사용, 책임성 확보를 거쳐 궁극적으로 비용 대비 가치(VFM) 실현으로 발전한다"는 단계적 발전 모델을 제시했다. 이 모델이 강조하는 핵심 내용으로 가장 적절한 것은? | E45: 공공조달의 핵심 목적은 기초적인 관련 법령과 규정을 준수하는 단계에 확고히 도달한 이후에는, 질적으로 더 이상 진화하거나 새로운 차원으로 발전하지 않고 정체된다. | F45: 공공조달의 목적은 발전 단계가 거듭될수록 점차 확대 및 심화되며, 궁극적으로는 비용 대비 가치(VFM) 실현이라는 가장 고도화된 정책적 목표를 향해 지속 나아간다. | G45: 해당 모델은 민간 기업의 단순 구매 관행을 설명하는 고전 이론으로, 복합적인 공공성을 지닌 정부의 공공조달 시스템이나 정책적 발전 과정과는 사실상 전혀 무관하다. | H45: 공공조달 시스템은 제도의 도입 초기부터 성숙 단계에 이르기까지, 어떠한 외부 환경 변화에도 항상 동일한 수준의 기초적인 단순 물품 확보 목적만을 지속적으로 추구한다. | I45: 2 | J45: * 정답 (②): 공공조달의 목적과 역할은 고정되어 있는 것이 아니라, 단순한 물품 확보라는 기초적 수준에서 출발해 규정 준수, 효율성, 책임성을 거쳐 최종적으로 '비용 대비 가치(VFM)'를 창출하는 심화된 수준으로 끊임없이 발전해 나간다는 점을 시사함.
A46: 43 | B46: 3. 공공조달의 특성 | C46: 2. 공공조달의 조달행위 특성 | D46: 사기업의 구매 부서와 달리, 국가나 공공기관의 조달 업무 담당자에게 고도의 윤리의식과 공공성, 그리고 무거운 책임성이 그 무엇보다 강하게 요구되는 가장 근본적인 이유는? | E46: 조달 사업에 투입되어 지출되는 모든 자금의 원천이 전적으로 국민이 피땀 흘려 납부한 신성한 세금(Tax)으로 조성된 공적 자금이기 때문이다. | F46: 공공조달 시장에서 연간 집행되는 전체 예산의 절대적인 규모와 그에 따른 경제적 파급력이 국가 거시 경제 지표에 막대한 영향을 미치기 때문이다. | G46: 세계무역기구 정부조달협정(WTO GPA) 가입국으로서 국제 사회가 요구하는 엄격하고 글로벌한 투명성 기준을 의무적으로 준수해야 하기 때문이다. | H46: 수요 파악부터 입찰 공고, 적격심사, 낙찰, 그리고 계약 해제 및 지체상금 부과에 이르는 관련 법령과 행정 절차가 사기업에 비해 매우 복잡하기 때문이다. | I46: 1 | J46: * 정답 (①): 조달 절차의 복잡성이나 경제적 파급력도 이유가 되지만, 조달 공무원에게 요구되는 청렴과 책임성의 가장 근원적인 잣대는 사용처의 재원이 '국민의 혈세'라는 점에 있습니다.
A47: 44 | B47: 3. 공공조달의 특성 | C47: 2. 공공조달의 조달행위 특성 | D47: 조달 업무의 실무적 흐름을 보여주는 전체 라이프사이클을 6단계로 도식화할 때, 다음 빈칸에 들어갈 가장 알맞은 단계 명칭은? [조달계획 수립] → [조달 실행(입찰/계약)] → [계약 이행(납품) 관리] → [ 빈칸 ] → [공급자 성과 평가] → [차기 계획 피드백] | E47: 외부 민간 시장에 해당 조달 건의 세부 과업 내역을 널리 알리고 역량 있는 다수 업체의 경쟁적 참여를 유도하는 입찰 공고 단계 | F47: 참여 업체의 재무 건전성, 과거 납품 실적, 기술 인력 보유 현황 등 적합한 기준을 갖추었는지 꼼꼼히 검증하는 적격 자격 심사 단계 | G47: 물품의 획득이나 서비스 제공 중 예기치 않게 발생하는 각종 하자에 대해 책임 소재를 명확히 묻고 이를 무상으로 보완하는 사후 보증 단계 | H47: 계약상대자의 최종 납품 검수를 무사히 통과하고 사전에 약정된 대금을 관계 법령에 따라 정산하여 지급을 완료하는 계약 완료 단계 | I47: 4 | J47: * 정답 (④): 계약 이행(물품 납품 및 용역 수행)이 마무리되면, 검사/검수를 거쳐 대금을 지급하는 '계약 완료(종결)' 단계로 이어집니다. 이후 해당 업체의 성과를 평가하여 다음 계획에 피드백합니다.
A48: 45 | B48: 3. 공공조달의 특성 | C48: 2. 공공조달의 조달행위 특성 | D48: 막대한 예산이 투입되는 공공조달 업무를 성공적으로 완수하고 예산 낭비를 막기 위해, 발주처인 조달기관이 가장 중점을 두고 통제 및 관리해야 할 핵심 사항은? | E48: 수요 부서의 최초 조달 요구사항 분석 및 기획부터 시작하여, 입찰 공고, 낙찰자 선정, 물품 납품(이행), 그리고 사후 하자 평가에 이르기까지 구매 전·중·후의 전 과정을 유기적인 생애주기로 묶어 총체적으로 관리한다. | F48: 공급자의 물품 납품 및 최초 설치가 정상적으로 완료된 이후에 발생하는 시스템 오류 및 유지보수 등 사후 영역은 전적으로 해당 물품을 쓰는 사용 부서의 책임이므로 조달 부서의 관리 대상에서 엄격히 제외한다. | G48: 국가 예산 절감이 그 무엇보다 가장 중요한 가치이므로, 초기 서류 심사나 입찰 단계를 대폭 간소화하고 오로지 낙찰자와의 최종 가격 협상 과정에만 기관의 행정력을 집중적으로 투입하여 가격을 깎는 데 주력한다. | H48: 계약이 최종적으로 체결되고 도장이 찍히는 시점의 법적 하자가 없는지가 향후 감사에서 가장 중요하게 다뤄지므로, 실제 이행 과정보다는 구매 및 계약이 성립하는 단일 행정 시점만을 중점적으로 서류상 관리한다. | I48: 1 | J48: * 정답 (①): 현대적 공공조달 관리는 특정 시점의 단편적인 구매 행위 중심에서 벗어나, 사업의 기획 단계부터 계약 종결 및 폐기/사후 평가에 이르는 전체 생애주기(Life-Cycle)를 통합 관리하는 것을 핵심으로 합니다.
A49: 46 | B49: 3. 공공조달의 특성 | C49: 2. 공공조달의 조달행위 특성 | D49: 국민의 세금을 재원으로 하는 공공계약의 고유한 행정적 특징으로 가장 올바른 것은? | E49: 규정 위반 시 대외적 효력이 전면 무효화된다. | F49: 최종 결과보다는 합법적 절차와 과정을 중시한다. | G49: 상업적 이윤을 투명성보다 우선시하는 경향이 있다. | H49: 법령의 모든 조문은 재량권이 배제된 강행규정이다. | I49: 2 | J49: * 정답 (②): 공공조달은 세금을 집행하므로 절차적 정당성(과정)을 매우 중시합니다. 훈시규정 위반 시 무조건 무효화되는 것은 아니며 재량규정도 존재합니다.
A50: 47 | B50: 4. 공공조달의 구성체계 | C50: 1. 조직적 구성체계 | D50: [상황] 공공조달의 구성요소를 '법적 근거', '이를 운영하는 조직', '실제 업무가 처리되는 수단'으로 나눠 설명하려 한다. 이 중 '실제 업무가 처리되는 수단'에 해당하는 것은? | E50: 국가 공공조달 업무의 실무적 집행을 총괄하는 중앙행정기관인 조달청 | F50: 국가계약제도의 핵심 정책 수립을 총괄 담당하는 재정경제부 계약정책과 | G50: 공공조달 제도의 기본적 법적 근거인 '국가를 당사자로 하는 계약에 관한 법률' | H50: 실제 조달 업무가 전산상으로 처리되는 국가종합전자조달시스템(나라장터) | I50: 4 | J50: * 정답 (④): 나라장터는 실제 조달 업무가 처리되는 운영적 수단이며, 국가계약법은 법적 근거, 재정경제부·조달청은 이를 운영하는 조직에 해당함.
A51: 48 | B51: 4. 공공조달의 구성체계 | C51: 1. 조직적 구성체계 | D51: [상황] 신임 실무자가 신규 사업 추진을 위해 공공조달 업무 프로세스를 정리하고 있다. 다음 중 공공조달의 표준적인 계약 추진 절차를 시간 흐름에 따라 가장 올바르게 나열한 것은? | E51: [개찰 및 심사] → [공식 입찰공고] → [사업 수요제기] → [낙찰자 선정] → [사전규격공개] → [입찰서류 제출] → [최종 계약체결] | F51: [공식 입찰공고] → [사업 수요제기] → [최종 계약체결] → [사전규격공개] → [입찰서류 제출] → [개찰 및 심사] → [낙찰자 선정] | G51: [사전규격공개] → [사업 수요제기] → [입찰서류 제출] → [개찰 및 심사] → [최종 계약체결] → [공식 입찰공고] → [낙찰자 선정] | H51: [사업 수요제기] → [사전규격공개] → [공식 입찰공고] → [입찰서류 제출] → [개찰 및 심사] → [낙찰자 선정] → [최종 계약체결] | I51: 4 | J51: * 정답 (④): 공공조달은 발주기관의 '수요제기'를 시작으로, 업계 의견 수렴을 위한 '사전규격공개'와 '입찰공고'를 거쳐, '입찰서 제출 및 개찰', 적격심사 등을 통한 '낙찰자 선정' 후 최종적으로 '계약 체결'에 이르는 일련의 흐름을 따릅니다.
A52: 49 | B52: 4. 공공조달의 구성체계 | C52: 1. 조직적 구성체계 | D52: [상황] 조달 담당자가 공급업체를 탐색해 적합한 후보군을 추리는 '소싱(Sourcing)' 단계를 막 끝냈다. 다음으로 진행해야 할 업무 단계로 가장 적절한 것은? | E52: 내부 조달수요를 다시 식별하는 단계로 되돌아간다 | F52: 곧바로 낙찰자를 선정하는 단계로 건너뛴다 | G52: 제출된 입찰서를 평가하는 단계로 곧바로 넘어간다(권유 절차 없이) | H52: 추린 후보군에게 입찰 참여를 권유하는 단계로 넘어간다 | I52: 4 | J52: * 정답 (④): 조달업무는 수요식별 → 공급업체탐색 → 소싱 → 입찰권유 → 입찰평가 순으로 이어지므로, 소싱 직후에는 입찰권유가 이루어짐.
A53: 50 | B53: 4. 공공조달의 구성체계 | C53: 1. 조직적 구성체계 | D53: [상황] 해외 선진 조달 행정 체계 벤치마킹을 위해 관련 자료를 수집하던 중, 각국의 조달 전담기관 운영 현황에 대해 실무자들이 나눈 대화 내용이다. 이 중 가장 타당한 설명은 무엇인가? | E53: 미국의 GSA나 영국의 CCS처럼 주요 선진국들은 대체로 국가 조달 정책을 수립하고 대규모 공동구매 사업을 총괄적으로 관리하는 별도의 전담 조달기관을 체계적으로 운영하고 있습니다. | F53: 조달 업무의 특수성으로 인해 해외 선진국들조차 정부 조달만을 전담하는 별도의 독립적인 국가 기관을 설립하여 운영하는 사례는 전 세계적으로 사실상 전혀 존재하지 않는 것으로 파악됩니다. | G53: 해외의 주요 조달기관들은 각 부처의 요구에 따라 단순한 물품 구매 대행 업무만을 기계적으로 수행할 뿐, 거시적인 조달 정책을 기획하거나 제도를 개선하는 권한은 전혀 보유하지 않습니다. | H53: 글로벌 공공행정 개혁의 흐름에 따라 주요 선진국들의 국가 조달 전담기관들은 모두 동일한 특정 연도에 일괄적으로 설립되어 완벽히 똑같은 행정 기능과 조직적 역할을 수행하고 있습니다. | I53: 1 | J53: * 정답 (①): 미국 GSA, 영국 CCS 등 주요 선진국은 범정부 차원의 조달 정책 수립 및 공동구매를 총괄하는 전담기관을 두고 있음. 단, 각 기관의 구체적인 설립 시기나 세부 기능은 국가별 행정 환경에 따라 상이함.
...

Sheet 1-2_원칙및방법
A2: 공공조달과 법제도 이해 - 2. 공공조달 원칙 및 방법
A3: 번호 | B3: 세부항목 | C3: 세세항목 | D3: 문제 내용 | E3: 보기① | F3: 보기② | G3: 보기③ | H3: 보기④ | I3: 정답 번호 | J3: 해설 및 오답노트 | K3: 출처 | L3: 개정일자 | M3: 숫자문제
A4: 1 | B4: 1. 공공조달 원칙 | C4: 1. 공공조달 기본 원칙 | D4: [상황] 한 강사가 공공조달의 5대 기본원칙을 설명하며 '투명성, 비용대비가치, 경쟁성, 차별금지 및 동등대우, 책임성'을 언급했다. 다음 중 이 목록에 포함될 가능성이 가장 낮은 개념은? | E4: 투명성(Transparency) | F4: 책임성(Accountability) | G4: 경쟁성(Competitiveness) | H4: 수익성(Profitability) | I4: 4 | J4: * 정답 (④): 수익성은 민간구매의 최우선 목표이며, 공공조달의 5대 기본원칙(투명성·VFM·경쟁성·차별금지동등대우·책임성)에는 포함되지 않음.
A5: 2 | B5: 1. 공공조달 원칙 | C5: 1. 공공조달 기본 원칙 | D5: [상황] 발주기관이 사무기기를 구매하면서 구매가격뿐 아니라 유지보수 비용, 소모품 비용, 폐기 비용까지 함께 비교해 선정했다. 이러한 접근방식이 구현하는 원칙은? | E5: 차별금지 및 동등대우 | F5: 비용 대비 가치(VFM) | G5: 책임성 | H5: 경쟁성 | I5: 2 | J5: * 정답 (②): 구매가격 외에 유지보수·폐기 등 총소유비용까지 종합 고려하는 것은 비용 대비 가치(VFM) 원칙의 구현임.
A6: 3 | B6: 1. 공공조달 원칙 | C6: 1. 공공조달 기본 원칙 | D6: [상황] 한 공공기관의 조달 담당자가 신규 장비 도입을 위해 TCO(총소유비용)를 산정하면서, '장비의 최초 취득부터 운영, 그리고 최종 폐기까지 우리 기관이 실제로 지출하게 될 모든 비용'을 합산하여 집계했다. 이러한 산정 방식에 대한 평가로 가장 적절한 것은? | E6: 틀린 산정 방식이다. TCO는 장비의 최초 취득과 운영 기간의 유지보수 비용만을 합산하는 재무 지표이므로, 수명이 종료된 이후의 최종 폐기 단계에서 발생하는 각종 처리 비용은 원칙적으로 전면 제외하고 계산해야 한다. | F6: 올바른 산정 방식이다. 하지만 향후 감사에 대비해 객관성을 완벽히 입증하려면, 우리 기관의 실제 지출 비용 외에 입찰에 참여했던 타 경쟁업체들의 평균 제시 가격까지도 TCO 산출 내역에 반드시 포함시켜야만 한다. | G6: 올바른 산정 방식이다. TCO(총소유비용)는 자산의 최초 취득 단계부터 정비 등의 운영 기간을 거쳐 최종 폐기에 이르기까지, 해당 자산과 관련해 실질적으로 발생하는 모든 비용을 온전히 포괄하는 개념이기 때문이다. | H6: 틀린 산정 방식이다. 공공조달에서 TCO는 당해 예산 집행을 위해 장비를 최초 도입할 때 지급하는 초기 구매 가격만을 의미하므로, 향후에 지속적으로 발생하게 될 장기적인 운영 비용 및 폐기 비용은 제외해야 한다. | I6: 3 | J6: * 정답 (③): TCO(Total Cost of Ownership, 총소유비용)는 자산을 획득하고 유지·보수하며 최종적으로 폐기하는 전체 수명 주기 동안 실제 발생하는 모든 지출 비용을 합산한 포괄적 개념임. 경쟁업체의 가격을 억지로 포함시킬 필요가 없으며, 단순 초기 구매 비용만을 의미하지도 않음.
A7: 4 | B7: 1. 공공조달 원칙 | C7: 1. 공공조달 기본 원칙 | D7: [상황] 한 공공기관의 계약담당자가 입찰 공고가 정식으로 게시되기 전에, 평소 친분이 있던 특정 업체에게만 과업지시서 등 입찰 관련 핵심 정보를 미리 제공했다. 이러한 담당자의 행위가 위반하고 있는 공공조달의 기본 원칙으로 가장 적절한 것은? | E7: 특정 업체에 유리한 입찰 환경을 조성했으므로 '경쟁성 원칙'만을 단편적으로 위반한 것이며, 공공조달의 다른 핵심적인 기본 원칙들과는 직접적인 연관성이 없다. | F7: 계약 공고 이전의 단순한 절차적 하자에 해당할 뿐이므로, 공공 예산 집행에 대해 국민에게 엄중히 책임을 져야 한다는 '책임성 원칙'과는 사실상 전혀 무관하다. | G7: 예산을 절감하여 경제적 효율성을 달성해야 한다는 '비용 대비 가치 원칙'만을 단독으로 훼손한 것이며, 공공조달의 절차적 공정성 문제로 치부하기는 매우 어렵다. | H7: 잠재적 입찰자 모두에게 동등하게 정보를 공개해야 한다는 '투명성 원칙' 및 특정 업체를 부당하게 우대해서는 안 되는 '차별금지·동등대우 원칙'에 정면으로 반한다. | I7: 4 | J7: * 정답 (④): 특정 업체에만 사전 정보를 제공하는 행위는 입찰 관련 정보를 모든 이해관계자에게 투명하게 공개해야 한다는 '투명성 원칙'과 특정인을 유리하게 대우하지 않아야 한다는 '차별금지 및 동등대우 원칙'을 심각하게 훼손하는 부정행위임.
A8: 5 | B8: 1. 공공조달 원칙 | C8: 1. 공공조달 기본 원칙 | D8: [상황] 한 신임 계약담당자가 "향후 감사를 대비하여 공공조달의 책임성을 확보하려면, 무조건 가장 낮은 입찰 가격을 제시한 최저가 업체를 낙찰자로 선정하는 것이 가장 확실한 방법이다"라고 주장했다. 이 주장의 핵심적인 문제점은 무엇인가? | E8: 단순 가격 중심의 무조건적인 최저가 낙찰 방식은 오히려 조달 목적물의 품질 저하를 초래하여 '비용 대비 가치(VFM)' 원칙을 심각하게 훼손할 우려가 크므로, 진정한 의미의 책임성 확보 방안이 될 수 없다. | F8: 책임성 원칙은 예산 집행 과정의 경제성과는 전혀 무관한 독립적 개념이므로, 입찰 업체의 가격 제안 수준이나 구체적인 낙찰자 선정 방식 등 재무적인 요소들을 억지로 결부시켜 책임성을 논의하는 것은 잘못된 접근이다. | G8: 공공조달에서 의미하는 책임성이란 사후 감사 기관의 지적 사항을 회피하기 위한 소극적인 방어 기제에만 전적으로 국한되므로, 초기 입찰 단계에서의 가격 산정 문제나 낙찰자 결정 방식과는 근본적으로 아무런 관련성이 없다. | H8: 해당 주장은 아무런 문제가 없다. 국민의 혈세를 집행하는 공공조달의 특성상, 예산을 최대한 절감할 수 있는 무조건적 최저가 선정이 곧 투명하고 공정한 업무 처리이자 책임성을 완벽하게 입증하는 가장 핵심적인 지표이다. | I8: 1 | J8: * 정답 (①): 무조건적인 최저가 선정은 장기적인 품질과 효율성을 따지는 VFM(비용 대비 가치) 원칙을 훼손할 수 있음. 공공조달의 책임성은 단순한 가격 인하가 아니라 합리적 의사결정 과정, 꼼꼼한 기록 보관, 투명한 성과평가 등을 통해 확보됨.
A9: 6 | B9: 1. 공공조달 원칙 | C9: 1. 공공조달 기본 원칙 | D9: [상황] 신입 직원이 '공공조달은 수의계약을 기본으로 하고 경쟁입찰은 특별한 경우에만 쓰는 것 아니냐'고 물었다. 이에 대한 올바른 답변은? | E9: 아니다. 제한경쟁이 원칙이며 나머지가 예외이다 | F9: 아니다. 일반경쟁이 원칙이며, 제한경쟁·지명경쟁·수의계약이 예외적으로 허용된다 | G9: 맞다. 지명경쟁이 원칙이고 나머지가 보조수단이다 | H9: 맞다. 수의계약이 원칙이고 경쟁입찰이 예외이다 | I9: 2 | J9: * 정답 (②): 국가계약법 제7조는 일반경쟁을 원칙으로 규정하며, 제한경쟁·지명경쟁·수의계약은 예외적 방법임. | K9: 국가계약법 제7조
A10: 7 | B10: 1. 공공조달 원칙 | C10: 1. 공공조달 기본 원칙 | D10: [상황] 적격심사제도를 처음 접한 직원이 '결국 가격만 보고 낙찰자를 정하는 것 아니냐'고 물었다. 이 질문에 대한 올바른 답변은? | E10: 아니다. 입찰가격과 함께 계약이행능력(수행능력·재무상태·신인도 등)을 종합 심사한다 | F10: 아니다. 오직 재무상태만으로 결정한다 | G10: 맞다. 수행능력만 보고 가격은 보지 않는다 | H10: 맞다. 오직 가격만으로 결정한다 | I10: 1 | J10: * 정답 (①): 적격심사제도는 가격뿐 아니라 수행능력·재무상태·신인도 등 계약이행능력을 종합적으로 심사하는 제도임.
A11: 8 | B11: 1. 공공조달 원칙 | C11: 1. 공공조달 기본 원칙 | D11: 국가계약법령 및 조달사업법령의 취지에 비추어 볼 때, 공공조달 업무 수행 시 요구되는 핵심 기본원칙에 해당하지 않는 것은? | E11: 조달 절차와 심사 기준을 외부로 투명하게 공개하여 조달 행정에 대한 국민적 신뢰를 확보하는 투명성 유지의 원칙 | F11: 다수의 유효한 공급자에게 입찰에 참여할 수 있는 동등한 기회를 부여하여 시장의 활력을 높이는 경쟁성 확보의 원칙 | G11: 특정 조달기업과의 장기적이고 반복적인 거래 관계를 우선적으로 보호하여 공급망을 고착화하는 지속성 유지의 원칙 | H11: 투입된 국가 예산 대비 최적의 품질과 효용을 추구하여 재정 지출의 효율성을 극대화하는 비용대비 가치 창출의 원칙 | I11: 3 | J11: * 정답 (③): 공공조달은 공정성과 경쟁성을 중시하므로, 특정 기업과의 거래를 고착화하여 기회균등을 저해하는 '지속성 유지'는 기본원칙이 될 수 없습니다.
A12: 9 | B12: 1. 공공조달 원칙 | C12: 1. 공공조달 기본 원칙 | D12: 국가계약법령의 기본 이념에 비추어 볼 때, 공공조달 제도를 운영함에 있어 반드시 지켜야 할 3대 원칙으로 볼 수 없는 것은? | E12: 합리적인 기준 없이 특정 기업에 부당한 특혜를 주거나 불이익을 강요하는 행위를 원천적으로 차단하는 차별금지의 원칙 | F12: 조달 사업 수행 과정에서 공공기관의 재무적 이익과 잉여금을 극대화하여 국고에 환수하도록 규정하는 수익 창출의 원칙 | G12: 공공 입찰과 관련된 모든 정보와 평가 기준을 외부로 명확하게 공개하여 절차적 정당성을 확보하는 투명성 유지의 원칙 | H12: 자격 요건을 갖춘 다수의 적격 공급자에게 입찰에 참여할 수 있는 동등한 기회를 균등하게 보장하는 경쟁 확보의 원칙 | I12: 2 | J12: * 정답 (②): 공공조달은 국가 예산을 재원으로 공공성을 실현하는 것이 목적이므로, 민간 기업처럼 조달 자체를 통한 '재무적 수익 창출'을 원칙으로 삼지 않습니다.
A13: 10 | B13: 1. 공공조달 원칙 | C13: 1. 공공조달 기본 원칙 | D13: 공공기관의 계약 및 지출 업무 담당자가 조달 업무 수행 시 원칙적으로 '경쟁적 조달 방법(경쟁입찰)'을 우선적으로 선택하여 설계해야 하는 가장 타당하고 중요한 법리적 근거는? | E13: 조달청의 적격심사 및 낙찰자 선정 과정이 시스템을 통해 완벽히 정형화되어 있어, 경험이 부족한 실무자의 행정 편의성과 업무 효율성이 수의계약 대비 대폭 향상되기 때문이다. | F13: 수의계약 시 발생할 수 있는 잦은 유찰의 위험이나 업체 간의 분쟁 소지가 적고, 궁극적으로 발주기관이 필요한 물자를 최종적으로 획득하는 데 걸리는 전체 조달 기간이 단축되기 때문이다. | G13: 오랜 기간 거래해 오며 제품의 품질이 이미 검증된 신뢰할 수 있는 특정 우수 조달기업의 몫을 확실히 챙겨주어 그들의 안정적 매출 규모를 정책적으로 보호해 줄 수 있기 때문이다. | H13: 국가 세금을 사용하는 조달 행정의 근간인 공공성 확보, 절차적 투명성 보장, 그리고 관련 업계의 기회균등이라는 공공조달 제도의 확고한 대원칙을 준수하기 위한 최우선 전제 조건이기 때문이다. | I13: 4 | J13: * 정답 (④): 조달의 기본 이념인 경쟁, 투명성, 차별금지를 공정하게 실현하는 가장 완벽하고 원칙적인 방법론이 바로 지정정보처리장치를 통한 공개 경쟁입찰입니다.
A14: 11 | B14: 1. 공공조달 원칙 | C14: 1. 공공조달 기본 원칙 | D14: 공공조달 제도를 공정하고 굳건하게 지탱하기 위해, 실무자와 기업이 가슴에 새기고 각종 법령에서 엄격하게 규정하고 있는 '3대 기본원칙(Core Principles)'을 가장 바르게 나열한 것은? | E14: 행정상 불필요한 비용을 과감히 단축하는 절차적 편의성의 원칙, 다양한 사회적 가치를 포괄적으로 실현하는 포용성의 원칙, 납품 결과에 끝까지 책임지는 사후관리 보장의 원칙 | F14: 장기간의 안정적이고 익숙한 거래를 유도하는 공급망 지속성의 원칙, 영세한 지역 중소기업을 무조건적으로 보호하는 상생협력의 원칙, 첨단 신기술을 우대하는 기술 혁신성의 원칙 | G14: 특정 자격 요건을 갖춘 자에게 참여 기회균등을 보장하는 경쟁의 원칙, 정당한 이유 없이 특정 업체를 배제하지 않는 차별금지 원칙, 심사 기준과 절차를 투명하게 공개하는 투명성의 원칙 | H14: 투입되는 국가 예산 대비 산출 효율을 무조건적으로 높이는 경제성 제일주의 원칙, 무역협정에도 불구하고 국내 기업을 무조건 우대하는 자국우대 원칙, 공정성을 중시하는 도덕적 책임의 원칙 | I14: 3 | J14: * 정답 (③): 공공조달의 흔들림 없는 3대 대원칙은 다수의 입찰을 유도하는 '경쟁', 국적이나 기업 규모를 이유로 한 부당한 진입 장벽을 없애는 '차별금지', 입찰 전 과정의 정보를 사전에 고지하는 '투명성'입니다.
A15: 12 | B15: 1. 공공조달 원칙 | C15: 2. 공공조달 실행 원칙 | D15: [상황] 어느 기관이 조달 계획을 예산 편성·재정 관리 계획과 긴밀히 연계하여 운영하기로 했다. 이러한 접근이 구현하는 실행원칙으로 가장 적절한 것은? | E15: 참여(Participation) | F15: 통합(Integration) | G15: 평가(Evaluation) | H15: 균형성(Balance) | I15: 2 | J15: * 정답 (②): 조달을 재정관리·예산편성이라는 더 큰 틀과 연계해 운영하는 것은 통합(Integration) 원칙의 구현임.
A16: 13 | B16: 1. 공공조달 원칙 | C16: 2. 공공조달 실행 원칙 | D16: [상황] 조달정책 담당자가 '중소기업이 서류 제출 부담 때문에 공공입찰 참여를 포기하는 사례가 많다'는 지적을 받고, 관련 행정절차를 간소화하기로 했다. 이 조치가 구현하는 실행원칙로 가장 적절한 것은? | E16: 참여(Participation) | F16: 통합(Integration) | G16: 균형성(Balance) | H16: 접근성(Access) | I16: 4 | J16: * 정답 (④): 중소기업 등의 시장 진입 장벽(행정 부담 등)을 낮추는 조치는 접근성(Access) 원칙의 구현임.
A17: 14 | B17: 1. 공공조달 원칙 | C17: 2. 공공조달 실행 원칙 | D17: [상황] 한 기관이 평가위원의 이해충돌 여부를 사전에 점검하고, 뇌물·향응 수수를 엄격히 금지하는 내부 규정을 강화했다. 이 조치가 구현하는 실행원칙로 가장 적절한 것은? | E17: 균형성(Balance) | F17: 청렴성(Integrity) | G17: 효율성(Efficiency) | H17: 참여(Participation) | I17: 2 | J17: * 정답 (②): 이해충돌 점검, 뇌물·향응 금지는 부패·사기를 예방하고 높은 윤리기준을 유지하는 청렴성(Integrity) 원칙의 구현임.
A18: 15 | B18: 1. 공공조달 원칙 | C18: 2. 공공조달 실행 원칙 | D18: 다음 설명이 공통적으로 가리키고 있는 공공조달의 5대 핵심 실행 원칙은? [설명] 공공기관이 조달 과정에서 단순히 최저가격을 추구하는 것을 넘어, 투입된 예산 대비 대상물의 품질, 내구성, 사후 유지비용 등을 종합적으로 고려하여 최적의 효용과 성과를 획득하는 것 | E18: 자격을 갖춘 다수의 공급자에게 동등하고 균등한 참여 기회를 폭넓게 제공하여 시장의 활력을 유도하는 경쟁성 확보의 원칙 | F18: 조달 행정의 최종 결과 및 절차적 정당성에 대해 담당자가 엄격한 책임을 지고 사후 검증을 수용하는 조달 책임성의 원칙 | G18: 입찰에 투입되는 한정된 국가 예산 대비 최적의 품질과 장기적 효용을 구하여 재정 효율성을 높이는 비용대비 가치의 원칙 | H18: 조달 과정 전반의 정보를 외부에 명확히 공개하여 공정성을 입증하고 정보의 비대칭성을 해소하는 투명성 유지의 원칙 | I18: 3 | J18: * 정답 (③): 가격 중심의 단편적 평가를 벗어나 생애주기비용(LCC)과 품질을 아울러 판단하는 것은 '비용대비 가치(Value for Money)' 원칙에 대한 설명입니다.
A19: 16 | B19: 1. 공공조달 원칙 | C19: 2. 공공조달 실행 원칙 | D19: 공공조달의 12대 원칙 중 시장에 대한 ‘참여(Participation)’ 원칙이 배제되거나 원활하게 작동하지 않을 때 우려되는 가장 치명적인 문제점은? | E19: 시장 진입 장벽이 인위적으로 높아짐에 따라 소수의 기존 공급자만이 조달 시장을 장악하는 폐쇄적인 독과점 구조가 고착화된다. | F19: 새로운 업체의 시장 진입 장벽이 지나치게 낮아져 자격 미달 업체의 난립 현상이 발생하고 계약 불이행 사태가 빈발하게 된다. | G19: 소수의 우량 업체 간 담합 횟수가 현저히 줄어들고 입찰 과정의 공정성과 투명성이 오히려 긍정적인 방향으로 강화되는 결과를 낳는다. | H19: 조달 시장에 참여하는 유효 경쟁 기업의 수가 줄어들어 조달청 등 발주기관의 계약 행정 업무 전문성이 과도하게 고도화된다. | I19: 1 | J19: * 정답 (①): 참여 기회가 차단되면 경쟁이 사라지고, 기존에 진입한 시장 지배적 사업자들만이 입찰을 독식하여 국가 예산의 낭비를 초래하게 됩니다.
A20: 17 | B20: 1. 공공조달 원칙 | C20: 2. 공공조달 실행 원칙 | D20: 공공조달의 선순환을 위한 ‘성과 평가(Evaluation)’ 기능이 제대로 작동하지 않을 경우 발생할 수 있는 행정적 위험 요소로 가장 거리가 먼 것은? | E20: 측정 가능한 객관적 핵심성과지표(KPI)가 부족하여 장기적인 관점에서 공공조달 시스템의 정책적 효과성 분석이 심각하게 제한된다. | F20: 과거 조달 사업에 대한 피드백 루프가 단절되어, 향후 유사한 사업의 조달 계획을 수립할 때 과거의 행정 오류가 그대로 반복될 수 있다. | G20: 분산된 조달 데이터가 일관되게 수집 및 정제되지 않아 통계의 신뢰성이 하락하고, 데이터 기반의 과학적인 의사결정에 활용하기 어렵다. | H20: 재정 지출 과정 전반에 대한 촘촘한 감시망이 소홀해져 횡령, 사기, 입찰 담합, 공적 자금 오남용 등 범죄 발생 위험이 직접적으로 증가한다. | I20: 4 | J20: * 정답 (④): 횡령, 자금 오남용 등의 부패 범죄는 사후적인 '성과 평가'의 부재라기보다는 내부 통제 및 '위험 관리(Risk Management)' 시스템이 미흡할 때 발생하는 직접적 위험 요소입니다.
A21: 18 | B21: 2. 공공조달 유형 | C21: 1. 중앙집중형 공공조달 | D21: 조달사업법령상 조달청에 원칙적으로 의무 구매를 요청해야 하는 '수요물자'의 품류에 해당하는 것은? | E21: 보관이 까다로운 각종 신선 식료품류 | F21: 관리가 필요한 살아있는 동·식물류 | G21: 행정 인프라에 쓰이는 일반 기계장치류 | H21: 기밀 유지가 필요한 무기 및 총포·화약류 | I21: 3 | J21: * 정답 (③): 식료품, 동·식물, 무기류는 특수성 탓에 조달청 의무 요청 대상에서 제외(자체 구매)되나, 기계장치류는 수요물자에 해당합니다.
... A23: 20 | B23: 2. 공공조달 유형 | C23: 2. 분산형 공공조달 | D23: 조달청장이 수요기관의 요청 물품을 해당 수요기관이 '직접 구매하도록 위임'할 수 있는 사유로 틀린 것은? | E23: 긴급한 재난 복구로 인해 조달청을 거치면 적기에 수요를 충족하기 어려운 경우 | F23: 조달청 내부 행정 절차상 수의계약을 체결하는 것이 매우 번거롭고 까다로운 경우 | G23: 시중 거래가 없는 신규 개발품으로 수요기관의 특수 기술과 전문성이 요구되는 경우 | H23: 국방·안보상의 사정 등으로 수요기관이 직접 구매하는 것이 국가에 명백히 유리한 경우 | I23: 2 | J23: * 정답 (②): 조달 위임은 긴급성, 안보 등 법적 사유가 있어야 하며, 단순히 조달청 입장에서 '수의계약 체결이 번거롭다'는 사유로 위임할 수 없습니다.
A24: 21 | B24: 3. 경쟁적 공공조달 방법 | C24: 1. 일반경쟁 | D24: [상황] 한 교육생이 '지명경쟁입찰이 국가계약법상 원칙적인 계약방법이고, 참가자격 제한이 없는 방식이 오히려 예외'라고 잘못 이해하고 있었다. 이 오해를 바로잡는 설명으로 가장 적절한 것은? | E24: 수의계약이 원칙이며 나머지가 예외이다 | F24: 그 이해가 맞다. 지명경쟁이 원칙이다 | G24: 참가자격 제한 없는 일반경쟁이 원칙이며, 지명경쟁은 예외적으로만 허용된다 | H24: 제한경쟁이 원칙이며 나머지가 예외이다 | I24: 3 | J24: * 정답 (③): 국가계약법상 원칙은 참가자격 제한이 없는 일반경쟁이며, 지명경쟁은 예외적 방법에 불과함. | K24: 국가계약법 제7조
A25: 22 | B25: 3. 경쟁적 공공조달 방법 | C25: 1. 일반경쟁 | D25: [상황] 발주기관이 인공위성 시스템처럼 기술적으로 매우 복잡해 사전에 완벽한 규격을 정하기 어려운 사업을 발주하려 한다. 먼저 가격을 제외한 기술제안서만 평가하고, 기술 적합 판정을 받은 업체만을 대상으로 이후 가격입찰을 실시해 낙찰자를 정하는 방식을 무엇이라 하는가? | E25: 적격심사낙찰제 | F25: 지명경쟁입찰 | G25: 협상에 의한 계약 | H25: 2단계 경쟁입찰 | I25: 4 | J25: * 정답 (④): 기술평가와 가격입찰을 단계적으로 분리해 진행하는 방식은 2단계 경쟁입찰이며, 기술 요구가 복잡해 사전 규격 확정이 어려운 사업에 활용됨.
A26: 23 | B26: 3. 경쟁적 공공조달 방법 | C26: 1. 일반경쟁 | D26: [상황] 발주기관이 대량의 표준 사무용품 구매에 2단계 경쟁입찰(기술평가+가격입찰 분리) 방식을 적용하려 한다. 이 선택에 대한 평가로 가장 적절한 것은? | E26: 적절하다. 표준화된 소모품 구매에도 항상 2단계 경쟁입찰을 적용해야 한다 | F26: 적절하다. 모든 물품 구매는 2단계 경쟁입찰이 원칙이다 | G26: 적절하지 않다. 표준 사무용품은 반드시 수의계약으로만 구매해야 한다 | H26: 적절하지 않다. 2단계 경쟁입찰은 기술적으로 복잡해 사전 규격 확정이 어려운 사업에 적합하며, 표준화된 사무용품에는 불필요한 절차 부담을 줄 수 있다 | I26: 4 | J26: * 정답 (④): 2단계 경쟁입찰은 기술 요구가 복잡해 사전 규격 확정이 어려운 사업에 적합하며, 표준화된 사무용품처럼 단순한 구매에는 오히려 불필요한 절차 부담을 줄 수 있음.
A27: 24 | B27: 3. 경쟁적 공공조달 방법 | C27: 1. 일반경쟁 | D27: [상황] 협상에 의한 계약에서 1순위 협상대상자와의 협상이 결렬되었다. 발주기관의 다음 조치로 가장 적절한 것은? | E27: 모든 절차를 처음부터 새로 시작해 재공고한다 | F27: 동일한 기준·절차에 따라 차순위 협상적격자와 협상을 이어간다 | G27: 1순위 업체와 가격만 다시 협상한다 | H27: 해당 사업을 자동으로 취소한다 | I27: 2 | J27: * 정답 (②): 협상에 의한 계약은 고득점자 순으로 순차 협상(연속협상)을 진행하며, 1순위와 결렬되면 차순위와 협상을 이어감.
A28: 25 | B28: 3. 경쟁적 공공조달 방법 | C28: 1. 일반경쟁 | D28: [상황] 전자역경매(ERA)를 도입한 기관에서 공급업체들의 납품 품질이 이전보다 다소 낮아졌다는 지적이 나왔다. 이 현상의 원인으로 가장 적절한 것은? | E28: 전자역경매는 담합을 조장하는 구조이기 때문이다 | F28: 전자역경매는 특정 업체에 대한 특혜를 유발하기 때문이다 | G28: 실시간 최저가 경쟁이 과열되면서 공급업체가 수익성 확보를 위해 품질을 낮출 유인이 생기기 때문이다 | H28: 전자역경매는 절차가 지나치게 복잡해 품질 관리가 어려워지기 때문이다 | I28: 3 | J28: * 정답 (③): 전자역경매는 실시간 최저가 발굴에는 효율적이지만, 과도한 가격 경쟁이 공급업체의 품질 저하·수익성 악화로 이어질 수 있다는 단점이 있음.
A29: 26 | B29: 3. 경쟁적 공공조달 방법 | C29: 1. 일반경쟁 | D29: 다수의 업체를 참여시키는 '경쟁입찰(Competitive Bidding)' 방식이 내포하고 있는 행정적 단점 또는 한계로 가장 적절한 것은? | E29: 까다로운 입찰 참가 자격 요건으로 인해 혁신적인 기술력을 갖춘 신생 조달기업의 입찰 참여 기회가 원천적으로 완벽히 차단된다. | F29: 법령에 정해진 표준화된 공개 절차와 공고 기간을 엄격히 준수해야 하므로 조달 물자의 최종 획득 완료까지 상당한 시간이 지연될 수 있다. | G29: 계약 체결 과정의 세부 평가 기준과 심사위원 명단 등 핵심 정보가 투명하게 공개되지 않아 절차적 공정성을 확보하기가 매우 어려워진다. | H29: 다수의 영세 업체가 무분별하게 참여함에 따라 업체 간의 기술 경쟁성이 과도하게 약화되어 최종 납품되는 대상물의 품질이 심각하게 저하된다. | I29: 2 | J29: * 정답 (②): 경쟁입찰은 공정성과 투명성을 담보하기 위해 사전 규격 공개, 공고 기간 준수, 서류 심사 등 엄격한 절차를 거치므로 필연적으로 조달 리드타임이 길어집니다.
A30: 27 | B30: 3. 경쟁적 공공조달 방법 | C30: 1. 일반경쟁 | D30: 우리나라의 국가계약법령 체계에서 명시적으로 규정하여 운영 중인 '3대 경쟁입찰 방식'을 가장 올바르게 묶은 것은? | E30: 불특정 다수를 대상으로 하는 공개경쟁입찰, 협상을 통해 낙찰자를 정하는 협상경쟁입찰, 종합 심사를 거치는 종합경쟁입찰 | F30: 가장 널리 쓰이는 일반경쟁입찰, 특정 조건을 갖춘 자로 제한하는 제한경쟁입찰, 발주자가 직접 업체를 지정하는 지명경쟁입찰 | G30: 특정 지역 업체로 한정하는 지역경쟁입찰, 지식재산권을 보호하기 위한 특허경쟁입찰, 다수의 공급자를 등록하는 다수공급자경쟁입찰 | H30: 예산 절감을 최우선으로 하는 최저가경쟁입찰, 물품의 규격을 심사하는 규격경쟁입찰, 협상 절차를 포함하는 복합경쟁입찰 | I30: 2 | J30: * 정답 (②): 법령상 경쟁입찰의 기본 형태는 참가 자격을 제한하지 않는 '일반경쟁'을 원칙으로 하며, 예외적인 요건을 충족할 경우 '제한경쟁' 및 '지명경쟁'을 허용하고 있습니다.
A31: 28 | B31: 3. 경쟁적 공공조달 방법 | C31: 1. 일반경쟁 | D31: 공공기관의 계약담당자가 특정 업체와의 수의계약 유혹을 뿌리치고 원칙에 따라 '경쟁입찰' 방식을 채택했을 때 실무적으로 얻을 수 있는 기대 효과와 가장 거리가 먼 것은? | E31: 발주기관의 재량권이 대폭 확대되어, 계약 체결 이후 상황 변화에 따라 과업지시서를 임의로 변경하거나 계약 조건을 발주자에게 유리하게 수정하는 등 계약변경의 자유가 완벽히 보장된다. | F31: 다수 업체의 치열한 투찰 가격 경쟁을 통해 시장의 합리적이고 객관적인 시장 가격(Market Price)이 자연스럽게 형성되고, 결과적으로 국고 예산이 눈에 띄게 절감된다. | G31: 다수의 예비 공급자 간의 선의의 기술 및 품질 경쟁을 유도하여, 더 뛰어난 기술력과 우수한 납품 역량을 갖춘 숨은 우량 공급자를 발굴하고 산업계 전반을 자극하고 촉진한다. | H31: 입찰 공고부터 적격심사, 최종 낙찰자 선정까지의 전 과정이 시스템을 통해 외부로 명명백백히 공개되므로 공공조달 행정 전반의 객관성과 대국민 투명성이 강력하게 강화된다. | I31: 1 | J31: * 정답 (①): 경쟁입찰은 사전에 확정하여 공고한 과업지시서와 계약 조건에 따라 투찰이 이루어지므로, 낙찰 후 기관이 임의로 과업을 변경하는 행위는 탈락한 타 업체의 기득권을 침해하는 위법 행위가 될 수 있어 오히려 계약 변경이 엄격히 통제됩니다.
A32: 29 | B32: 3. 경쟁적 공공조달 방법 | C32: 1. 일반경쟁 | D32: 누구나 참여할 수 있는 '일반경쟁입찰' 방식이 지니는 구조적 단점 및 위험 요소로 가장 타당한 것은? | E32: 기회균등 원칙 탓에 행정의 공평성이 심각하게 저해된다. | F32: 조달 절차가 투명하여 담당자의 통제력이 상실된다. | G32: 부실업체의 참여로 과당경쟁 및 품질 저하가 우려된다. | H32: 다수 업체 참여로 염가 계약이 체결되어 예산이 낭비된다. | I32: 3 | J32: * 정답 (③): 일반경쟁은 무분별한 부실업자 진입으로 인한 품질 저하 및 과당경쟁 위험이 가장 큰 단점으로 지적됩니다.
A33: 30 | B33: 3. 경쟁적 공공조달 방법 | C33: 1. 일반경쟁 | D33: 국가계약법령에 따라 발주기관이 선택할 수 있는 합법적인 정규 '경쟁입찰의 방법(방식)'에 해당하지 않는 것은? | E33: 능력이 검증된 5인 이상을 지명하는 지명경쟁입찰 | F33: 특정 객관적 실적으로 문턱을 높이는 제한경쟁입찰 | G33: 불특정 다수에게 기회를 개방하는 일반경쟁입찰 | H33: 온라인 경매로 실시간 최저가를 찾는 복수경쟁입찰 | I33: 4 | J33: * 정답 (④): 국가계약법상의 원칙적인 입찰 방식은 일반경쟁, 제한경쟁, 지명경쟁 등이며 '복수경쟁입찰'이라는 법적 분류는 존재하지 않습니다.
A34: 31 | B34: 3. 경쟁적 공공조달 방법 | C34: 1. 일반경쟁 | D34: 공공조달의 원칙적 방법인 '일반경쟁입찰'이 지니는 장단점에 대한 객관적 평가로 부적절하게 서술된 것은? | E34: 자격 미달 부실업체가 덤핑 투찰로 낙찰될 경우 심각한 계약 불이행 및 품질 저하 위험을 내포한다. | F34: 복잡한 적격자 선별 절차가 생략되어 공고부터 낙찰까지 행정 절차가 간소화되고 업무 부담이 준다. | G34: 다수 업체가 치열한 가격 경쟁을 벌여 예산 낭비를 막고 목적물을 염가에 구매할 가능성이 커진다. | H34: 모든 입찰 희망자에게 참가 자격을 폭넓게 부여하므로 공평성이 보장되고 대국민 신뢰도가 높아진다. | I34: 2 | J34: * 정답 (②): 일반경쟁은 제한이 없어 참가자가 폭증할 수 있으며, 이로 인해 제출된 서류 검토 및 심사 대상이 늘어나 오히려 행정 절차가 복잡해진다는 것이 큰 단점입니다.
A35: 32 | B35: 3. 경쟁적 공공조달 방법 | C35: 1. 일반경쟁 | D35: 공공계약의 일반 원칙 및 입찰 진행 절차에 대한 설명으로 가장 옳은 것은? | E35: 청렴계약을 위반한 경우 국가 안보 등과 무관하게 모든 계약을 해제해야 한다. | F35: 사업자등록증 등 고유번호증 서류 제출만으론 입찰참가자격이 자동 부여된다. | G35: 국가계약법령상 공공계약 체결 시 기본적으로 적용해야 하는 방식은 일반경쟁이다. | H35: 경쟁입찰은 단 1인의 유효한 입찰 참가자만 있어도 정상적으로 입찰이 성립된다. | I35: 3 | J35: 정답 (③) 일반경쟁입찰이 원칙임 / ① 국가안보 등 예외 시 유지 가능 / ② 추가 요건(면허 등) 필요 / ④ 2인 이상 유효입찰 필요 | K35: 계약법 제7조
A36: 33 | B36: 3. 경쟁적 공공조달 방법 | C36: 2. 제한경쟁 | D36: [상황] 계약담당공무원이 '평소 친분이 있는 업체와 계약하고 싶다'는 이유로 제한경쟁입찰의 참가자격을 좁게 설정하려 한다. 이 사유의 적법성에 대한 평가로 가장 적절한 것은? | E36: 적법 여부는 계약금액에 따라 달라진다 | F36: 적법하다. 담당자의 재량으로 자유롭게 정할 수 있다 | G36: 적법하지 않다. 개인적 선호는 제한경쟁의 적법한 사유가 될 수 없으며 공정성을 해치는 행위이다 | H36: 적법하다. 특수 기술 요건과 동일하게 취급된다 | I36: 3 | J36: * 정답 (③): 담당자의 개인적 선호는 제한경쟁의 적법한 사유가 될 수 없으며, 특수기술·설비 요구, 추정가격 기준 등 법령상 인정되는 사유만 정당함. | K36: 국가계약법 시행령 제21조
A37: 34 | B37: 3. 경쟁적 공공조달 방법 | C37: 2. 제한경쟁 | D37: 일반경쟁의 단점을 보완하기 위해 도입된 '제한경쟁입찰' 제도의 법적 기준과 운영 원칙에 대한 설명으로 올바른 것은? | E37: 중소기업 보호를 위해 고시금액 이하일 때만 영업소 소재지로 지역제한을 적용할 수 있다. | F37: 발주기관 임의로 2개 이상의 제한 기준(실적+지역 등)을 무제한으로 중복 적용할 수 있다. | G37: 일반경쟁의 부실업자 진입 단점을 보완하고 우량 업체의 경쟁을 유도하기 위한 제도이다. | H37: 특혜 시비를 차단하기 위해 실적 제한과 지역 제한을 동일 공고에 중복하는 것이 원칙이다. | I37: 3 | J37: * 정답 (③): 실적 및 지역 제한은 원칙적으로 중복 금지되며(특수 예외 있음), 지역제한은 고시금액 '미만(이하 아님)'일 경우에만 적용할 수 있습니다.
A38: 35 | B38: 3. 경쟁적 공공조달 방법 | C38: 2. 제한경쟁 | D38: 일반경쟁 단점을 보완하기 위해 고안된 '제한경쟁입찰' 제도의 법적·실무적 의의를 가장 정확하게 서술한 것은? | E38: 특정 업체 5인 이내만을 직접 지명하여 행정 소요일수를 획기적으로 단축하는 편의적 제도이다. | F38: 전국 단위로 개방하되 지역 업체의 투찰 금액을 일정 비율 할인해 주는 지역 상생 유인 제도이다. | G38: 신규 영세 업체의 진입을 유도하여 과당경쟁 부작용을 원천 해소하기 위한 특별 예외 제도이다. | H38: 부실업자 진입을 막고 우량 업체의 경쟁을 유도하는 일반과 지명경쟁의 중간적 보완 제도이다. | I38: 4 | J38: * 정답 (④): 제한경쟁입찰은 부실업체 진입(일반경쟁 단점)을 막고, 특혜 시비(지명경쟁 단점)를 줄이면서 일정 기준을 갖춘 다수의 경쟁을 유도하는 중간적 성격의 제도입니다.
A39: 36 | B39: 3. 경쟁적 공공조달 방법 | C39: 2. 제한경쟁 | D39: 지역제한 등 제한경쟁입찰의 적용 기준에 대한 설명으로 가장 옳은 것은? | E39: 국가기관의 지역제한은 고시금액 이상인 대규모 계약에 한정하여 엄격히 적용한다. | F39: 지자체가 물품제조실적으로 제한할 경우 그 기준은 행안부 고시금액 미만일 때이다. | G39: 지역제한 참가자는 입찰 공고일 하루만 해당 본점소재지를 유지하면 자격이 인정된다. | H39: 산업표준화법상 KS인증이나 우수단체표준인증 제품 등으로 입찰 참가자격을 제한할 수 있다. | I39: 4 | J39: 정답 (④) 품질 확보를 위해 인증 제품으로 제한 가능함 / ① 고시금액 미만 적용 / ② 고시금액 이상 / ③ 계약체결일까지 유지 | K39: 계약법 시행령
A40: 37 | B40: 3. 경쟁적 공공조달 방법 | C40: 2. 제한경쟁 | D40: 정부계약 제한경쟁입찰의 실적 및 자격 제한에 대한 설명으로 가장 옳은 것은? | E40: 국가기관이 실적으로 자격을 제한할 때는 계약목적물 규모의 1배 이내로 제한해야 한다. | F40: 농공단지 입주업체가 생산한 물품으로 참가자격을 제한하는 것은 법령상 전면 금지된다. | G40: 중소기업자간 제한경쟁 진행 시 타 법령에 명시된 제한 요건을 추가로 중복할 수 없다. | H40: 지역제한 대상자의 본점소재지는 입찰 당일에만 요건을 충족하면 유효하게 인정받는다. | I40: 1 | J40: 정답 (①) 과도한 진입장벽 방지를 위해 실적 제한은 1배 이내로 함 / ② 제한 가능 / ③ 중복 제한 가능 / ④ 계약일까지 유지 | K40: 계약법 시행령
A41: 38 | B41: 3. 경쟁적 공공조달 방법 | C41: 3. 지명경쟁 | D41: [상황] 한 담당자가 '지명경쟁입찰은 담당자가 신뢰하는 업체를 미리 골라 부르는 방식이라 오히려 공정성 시비가 적다'고 주장했다. 이 주장에 대한 평가로 가장 적절한 것은? | E41: 옳지 않다. 지명 과정에서 담당자의 주관이 개입될 소지가 있어 오히려 일반경쟁입찰보다 공정성 시비 가능성이 높다 | F41: 옳다. 지명경쟁은 원칙적 계약방법이라 문제되지 않는다 | G41: 지명경쟁과 공정성은 서로 무관한 개념이다 | H41: 옳다. 지명 절차가 있으므로 공정성 시비가 적다 | I41: 1 | J41: * 정답 (①): 지명 과정에서 담당자의 주관이 개입될 소지가 있어, 지명경쟁은 오히려 일반경쟁입찰보다 공정성 시비 가능성이 높음.
A42: 39 | B42: 3. 경쟁적 공공조달 방법 | C42: 3. 지명경쟁 | D42: 발주기관이 특정 업체를 직접 지정하는 '지명경쟁입찰' 제도의 특징과 주의사항에 대한 설명으로 틀린 것은? | E42: 유효 경쟁자가 10인 이내 소수일 경우 적용하는 등 제한경쟁입찰과는 뚜렷한 차이가 있다. | F42: 수의계약 대상이라도 특혜 시비를 줄이기 위해 지명경쟁입찰로 전환하여 집행할 수 있다. | G42: 특혜 시비를 없애기 위해 계약담당자는 사적 지인이 추천하는 업체를 우선적으로 지명해야 한다. | H42: 원칙적으로 5인 이상을 지명해야 하며, 최소 2인 이상이 참가해야 유효한 입찰로 성립된다. | I42: 3 | J42: * 정답 (③): 지명경쟁은 객관적인 기준과 협의를 통해 대상을 지명해야 하며, 사적 지인의 추천을 받아 지명하는 것은 심각한 특혜 및 유착 비리입니다. | K42: 국가계약법 시행령 제23조
...

Sheet 1-3_전자조달시스템
A2: 공공조달과 법제도 이해 - 3. 전자조달시스템
A3: 번호 | B3: 세부항목 | C3: 세세항목 | D3: 문제 내용 | E3: 보기① | F3: 보기② | G3: 보기③ | H3: 보기④ | I3: 정답 번호 | J3: 해설 및 오답노트 | K3: 출처 | L3: 개정일자 | M3: 숫자문제
A4: 1 | B4: 1. 전자조달시스템 개요 | C4: 1. 전자조달시스템 개념 | D4: [상황] 한 신입 직원이 '전자조달은 그냥 정부가 인터넷으로 물건 사는 거 아니냐'고 간단히 이해하고 있었다. 이 이해를 보완하는 정확한 설명으로 가장 적절한 것은? | E4: 전자조달은 ICT를 기반으로 조달 계획 수립부터 대금지급까지 전 과정을 온라인으로 처리해 공정성·투명성을 실현하는 시스템·방식이다 | F4: 전자조달은 계약은 오프라인, 대금지급만 온라인으로 이뤄지는 방식이다 | G4: 전자조달은 개인이 쇼핑몰에서 물건을 사는 것과 동일한 개념이다 | H4: 전자조달은 기업 간 상거래 전반을 가리키는 일반적 용어이다 | I4: 1 | J4: * 정답 (①): 전자조달은 ICT 기반으로 조달의 전 과정을 온라인화해 공정성·투명성 등 공공가치를 실현하는 시스템·방식임.
